Request sent to FastAPI backend.
Successful response received from FastAPI backend.
Request sent to FastAPI backend.
Successful response received from FastAPI backend.
Request sent to FastAPI backend.
Successful response received from FastAPI backend.
Request sent to FastAPI backend.
Successful response received from FastAPI backend.
Request sent to FastAPI backend.
Successful response received from FastAPI backend.
Request sent to FastAPI backend.
Successful response received from FastAPI backend.
Request sent to FastAPI backend.
Successful response received from FastAPI backend.
Request sent to FastAPI backend.
Successful response received from FastAPI backend.
Request sent to FastAPI backend.
Successful response received from FastAPI backend.
Request sent to FastAPI backend.
Successful response received from FastAPI backend.
Request sent to FastAPI backend.
Successful response received from FastAPI backend.
An error occurred: ('Connection aborted.', ConnectionResetError(10054, 'An existing connection was forcibly closed by the remote host', None, 10054, None))
Traceback (most recent call last):
  File "C:\Users\harsh\miniconda3\Lib\site-packages\urllib3\connectionpool.py", line 790, in urlopen
    response = self._make_request(
               ^^^^^^^^^^^^^^^^^^^
  File "C:\Users\harsh\miniconda3\Lib\site-packages\urllib3\connectionpool.py", line 536, in _make_request
    response = conn.getresponse()
               ^^^^^^^^^^^^^^^^^^
  File "C:\Users\harsh\miniconda3\Lib\site-packages\urllib3\connection.py", line 461, in getresponse
    httplib_response = super().getresponse()
                       ^^^^^^^^^^^^^^^^^^^^^
  File "C:\Users\harsh\miniconda3\Lib\http\client.py", line 1423, in getresponse
    response.begin()
  File "C:\Users\harsh\miniconda3\Lib\http\client.py", line 331, in begin
    version, status, reason = self._read_status()
                              ^^^^^^^^^^^^^^^^^^^
  File "C:\Users\harsh\miniconda3\Lib\http\client.py", line 292, in _read_status
    line = str(self.fp.readline(_MAXLINE + 1), "iso-8859-1")
               ^^^^^^^^^^^^^^^^^^^^^^^^^^^^^^
  File "C:\Users\harsh\miniconda3\Lib\socket.py", line 707, in readinto
    return self._sock.recv_into(b)
           ^^^^^^^^^^^^^^^^^^^^^^^
ConnectionResetError: [WinError 10054] An existing connection was forcibly closed by the remote host

During handling of the above exception, another exception occurred:

Traceback (most recent call last):
  File "C:\Users\harsh\miniconda3\Lib\site-packages\requests\adapters.py", line 486, in send
    resp = conn.urlopen(
           ^^^^^^^^^^^^^
  File "C:\Users\harsh\miniconda3\Lib\site-packages\urllib3\connectionpool.py", line 844, in urlopen
    retries = retries.increment(
              ^^^^^^^^^^^^^^^^^^
  File "C:\Users\harsh\miniconda3\Lib\site-packages\urllib3\util\retry.py", line 470, in increment
    raise reraise(type(error), error, _stacktrace)
          ^^^^^^^^^^^^^^^^^^^^^^^^^^^^^^^^^^^^^^^^
  File "C:\Users\harsh\miniconda3\Lib\site-packages\urllib3\util\util.py", line 38, in reraise
    raise value.with_traceback(tb)
  File "C:\Users\harsh\miniconda3\Lib\site-packages\urllib3\connectionpool.py", line 790, in urlopen
    response = self._make_request(
               ^^^^^^^^^^^^^^^^^^^
  File "C:\Users\harsh\miniconda3\Lib\site-packages\urllib3\connectionpool.py", line 536, in _make_request
    response = conn.getresponse()
               ^^^^^^^^^^^^^^^^^^
  File "C:\Users\harsh\miniconda3\Lib\site-packages\urllib3\connection.py", line 461, in getresponse
    httplib_response = super().getresponse()
                       ^^^^^^^^^^^^^^^^^^^^^
  File "C:\Users\harsh\miniconda3\Lib\http\client.py", line 1423, in getresponse
    response.begin()
  File "C:\Users\harsh\miniconda3\Lib\http\client.py", line 331, in begin
    version, status, reason = self._read_status()
                              ^^^^^^^^^^^^^^^^^^^
  File "C:\Users\harsh\miniconda3\Lib\http\client.py", line 292, in _read_status
    line = str(self.fp.readline(_MAXLINE + 1), "iso-8859-1")
               ^^^^^^^^^^^^^^^^^^^^^^^^^^^^^^
  File "C:\Users\harsh\miniconda3\Lib\socket.py", line 707, in readinto
    return self._sock.recv_into(b)
           ^^^^^^^^^^^^^^^^^^^^^^^
urllib3.exceptions.ProtocolError: ('Connection aborted.', ConnectionResetError(10054, 'An existing connection was forcibly closed by the remote host', None, 10054, None))

During handling of the above exception, another exception occurred:

Traceback (most recent call last):
  File "D:\Projects\RAGs\frontend\app.py", line 32, in <module>
    response = requests.post(
               ^^^^^^^^^^^^^^
  File "C:\Users\harsh\miniconda3\Lib\site-packages\requests\api.py", line 115, in post
    return request("post", url, data=data, json=json, **kwargs)
           ^^^^^^^^^^^^^^^^^^^^^^^^^^^^^^^^^^^^^^^^^^^^^^^^^^^^
  File "C:\Users\harsh\miniconda3\Lib\site-packages\requests\api.py", line 59, in request
    return session.request(method=method, url=url, **kwargs)
           ^^^^^^^^^^^^^^^^^^^^^^^^^^^^^^^^^^^^^^^^^^^^^^^^^
  File "C:\Users\harsh\miniconda3\Lib\site-packages\requests\sessions.py", line 589, in request
    resp = self.send(prep, **send_kwargs)
           ^^^^^^^^^^^^^^^^^^^^^^^^^^^^^^
  File "C:\Users\harsh\miniconda3\Lib\site-packages\requests\sessions.py", line 703, in send
    r = adapter.send(request, **kwargs)
        ^^^^^^^^^^^^^^^^^^^^^^^^^^^^^^^
  File "C:\Users\harsh\miniconda3\Lib\site-packages\requests\adapters.py", line 501, in send
    raise ConnectionError(err, request=request)
requests.exceptions.ConnectionError: ('Connection aborted.', ConnectionResetError(10054, 'An existing connection was forcibly closed by the remote host', None, 10054, None))
Request sent to FastAPI backend.
Successful response received from FastAPI backend.
Request sent to FastAPI backend.
Successful response received from FastAPI backend.
Request sent to FastAPI backend.
Successful response received from FastAPI backend.
Request sent to FastAPI backend.
Successful response received from FastAPI backend.
Request sent to FastAPI backend.
Successful response received from FastAPI backend.
An error occurred: HTTPConnectionPool(host='localhost', port=9000): Max retries exceeded with url: /api/ragas (Caused by NewConnectionError('<urllib3.connection.HTTPConnection object at 0x00000208D69FD730>: Failed to establish a new connection: [WinError 10061] No connection could be made because the target machine actively refused it'))
Traceback (most recent call last):
  File "C:\Users\harsh\miniconda3\Lib\site-packages\urllib3\connection.py", line 203, in _new_conn
    sock = connection.create_connection(
           ^^^^^^^^^^^^^^^^^^^^^^^^^^^^^
  File "C:\Users\harsh\miniconda3\Lib\site-packages\urllib3\util\connection.py", line 85, in create_connection
    raise err
  File "C:\Users\harsh\miniconda3\Lib\site-packages\urllib3\util\connection.py", line 73, in create_connection
    sock.connect(sa)
ConnectionRefusedError: [WinError 10061] No connection could be made because the target machine actively refused it

The above exception was the direct cause of the following exception:

Traceback (most recent call last):
  File "C:\Users\harsh\miniconda3\Lib\site-packages\urllib3\connectionpool.py", line 790, in urlopen
    response = self._make_request(
               ^^^^^^^^^^^^^^^^^^^
  File "C:\Users\harsh\miniconda3\Lib\site-packages\urllib3\connectionpool.py", line 496, in _make_request
    conn.request(
  File "C:\Users\harsh\miniconda3\Lib\site-packages\urllib3\connection.py", line 395, in request
    self.endheaders()
  File "C:\Users\harsh\miniconda3\Lib\http\client.py", line 1326, in endheaders
    self._send_output(message_body, encode_chunked=encode_chunked)
  File "C:\Users\harsh\miniconda3\Lib\http\client.py", line 1085, in _send_output
    self.send(msg)
  File "C:\Users\harsh\miniconda3\Lib\http\client.py", line 1029, in send
    self.connect()
  File "C:\Users\harsh\miniconda3\Lib\site-packages\urllib3\connection.py", line 243, in connect
    self.sock = self._new_conn()
                ^^^^^^^^^^^^^^^^
  File "C:\Users\harsh\miniconda3\Lib\site-packages\urllib3\connection.py", line 218, in _new_conn
    raise NewConnectionError(
urllib3.exceptions.NewConnectionError: <urllib3.connection.HTTPConnection object at 0x00000208D69FD730>: Failed to establish a new connection: [WinError 10061] No connection could be made because the target machine actively refused it

The above exception was the direct cause of the following exception:

Traceback (most recent call last):
  File "C:\Users\harsh\miniconda3\Lib\site-packages\requests\adapters.py", line 667, in send
    resp = conn.urlopen(
           ^^^^^^^^^^^^^
  File "C:\Users\harsh\miniconda3\Lib\site-packages\urllib3\connectionpool.py", line 844, in urlopen
    retries = retries.increment(
              ^^^^^^^^^^^^^^^^^^
  File "C:\Users\harsh\miniconda3\Lib\site-packages\urllib3\util\retry.py", line 515, in increment
    raise MaxRetryError(_pool, url, reason) from reason  # type: ignore[arg-type]
    ^^^^^^^^^^^^^^^^^^^^^^^^^^^^^^^^^^^^^^^^^^^^^^^^^^^
urllib3.exceptions.MaxRetryError: HTTPConnectionPool(host='localhost', port=9000): Max retries exceeded with url: /api/ragas (Caused by NewConnectionError('<urllib3.connection.HTTPConnection object at 0x00000208D69FD730>: Failed to establish a new connection: [WinError 10061] No connection could be made because the target machine actively refused it'))

During handling of the above exception, another exception occurred:

Traceback (most recent call last):
  File "D:\Projects\RAG\frontend\app.py", line 32, in <module>
    response = requests.post(
               ^^^^^^^^^^^^^^
  File "C:\Users\harsh\miniconda3\Lib\site-packages\requests\api.py", line 115, in post
    return request("post", url, data=data, json=json, **kwargs)
           ^^^^^^^^^^^^^^^^^^^^^^^^^^^^^^^^^^^^^^^^^^^^^^^^^^^^
  File "C:\Users\harsh\miniconda3\Lib\site-packages\requests\api.py", line 59, in request
    return session.request(method=method, url=url, **kwargs)
           ^^^^^^^^^^^^^^^^^^^^^^^^^^^^^^^^^^^^^^^^^^^^^^^^^
  File "C:\Users\harsh\miniconda3\Lib\site-packages\requests\sessions.py", line 589, in request
    resp = self.send(prep, **send_kwargs)
           ^^^^^^^^^^^^^^^^^^^^^^^^^^^^^^
  File "C:\Users\harsh\miniconda3\Lib\site-packages\requests\sessions.py", line 703, in send
    r = adapter.send(request, **kwargs)
        ^^^^^^^^^^^^^^^^^^^^^^^^^^^^^^^
  File "C:\Users\harsh\miniconda3\Lib\site-packages\requests\adapters.py", line 700, in send
    raise ConnectionError(e, request=request)
requests.exceptions.ConnectionError: HTTPConnectionPool(host='localhost', port=9000): Max retries exceeded with url: /api/ragas (Caused by NewConnectionError('<urllib3.connection.HTTPConnection object at 0x00000208D69FD730>: Failed to establish a new connection: [WinError 10061] No connection could be made because the target machine actively refused it'))
Request sent to FastAPI backend.
Successful response received from FastAPI backend.
An error occurred: ('Connection aborted.', ConnectionResetError(10054, 'An existing connection was forcibly closed by the remote host', None, 10054, None))
Traceback (most recent call last):
  File "C:\Users\harsh\miniconda3\Lib\site-packages\urllib3\connectionpool.py", line 790, in urlopen
    response = self._make_request(
               ^^^^^^^^^^^^^^^^^^^
  File "C:\Users\harsh\miniconda3\Lib\site-packages\urllib3\connectionpool.py", line 536, in _make_request
    response = conn.getresponse()
               ^^^^^^^^^^^^^^^^^^
  File "C:\Users\harsh\miniconda3\Lib\site-packages\urllib3\connection.py", line 461, in getresponse
    httplib_response = super().getresponse()
                       ^^^^^^^^^^^^^^^^^^^^^
  File "C:\Users\harsh\miniconda3\Lib\http\client.py", line 1423, in getresponse
    response.begin()
  File "C:\Users\harsh\miniconda3\Lib\http\client.py", line 331, in begin
    version, status, reason = self._read_status()
                              ^^^^^^^^^^^^^^^^^^^
  File "C:\Users\harsh\miniconda3\Lib\http\client.py", line 292, in _read_status
    line = str(self.fp.readline(_MAXLINE + 1), "iso-8859-1")
               ^^^^^^^^^^^^^^^^^^^^^^^^^^^^^^
  File "C:\Users\harsh\miniconda3\Lib\socket.py", line 707, in readinto
    return self._sock.recv_into(b)
           ^^^^^^^^^^^^^^^^^^^^^^^
ConnectionResetError: [WinError 10054] An existing connection was forcibly closed by the remote host

During handling of the above exception, another exception occurred:

Traceback (most recent call last):
  File "C:\Users\harsh\miniconda3\Lib\site-packages\requests\adapters.py", line 667, in send
    resp = conn.urlopen(
           ^^^^^^^^^^^^^
  File "C:\Users\harsh\miniconda3\Lib\site-packages\urllib3\connectionpool.py", line 844, in urlopen
    retries = retries.increment(
              ^^^^^^^^^^^^^^^^^^
  File "C:\Users\harsh\miniconda3\Lib\site-packages\urllib3\util\retry.py", line 470, in increment
    raise reraise(type(error), error, _stacktrace)
          ^^^^^^^^^^^^^^^^^^^^^^^^^^^^^^^^^^^^^^^^
  File "C:\Users\harsh\miniconda3\Lib\site-packages\urllib3\util\util.py", line 38, in reraise
    raise value.with_traceback(tb)
  File "C:\Users\harsh\miniconda3\Lib\site-packages\urllib3\connectionpool.py", line 790, in urlopen
    response = self._make_request(
               ^^^^^^^^^^^^^^^^^^^
  File "C:\Users\harsh\miniconda3\Lib\site-packages\urllib3\connectionpool.py", line 536, in _make_request
    response = conn.getresponse()
               ^^^^^^^^^^^^^^^^^^
  File "C:\Users\harsh\miniconda3\Lib\site-packages\urllib3\connection.py", line 461, in getresponse
    httplib_response = super().getresponse()
                       ^^^^^^^^^^^^^^^^^^^^^
  File "C:\Users\harsh\miniconda3\Lib\http\client.py", line 1423, in getresponse
    response.begin()
  File "C:\Users\harsh\miniconda3\Lib\http\client.py", line 331, in begin
    version, status, reason = self._read_status()
                              ^^^^^^^^^^^^^^^^^^^
  File "C:\Users\harsh\miniconda3\Lib\http\client.py", line 292, in _read_status
    line = str(self.fp.readline(_MAXLINE + 1), "iso-8859-1")
               ^^^^^^^^^^^^^^^^^^^^^^^^^^^^^^
  File "C:\Users\harsh\miniconda3\Lib\socket.py", line 707, in readinto
    return self._sock.recv_into(b)
           ^^^^^^^^^^^^^^^^^^^^^^^
urllib3.exceptions.ProtocolError: ('Connection aborted.', ConnectionResetError(10054, 'An existing connection was forcibly closed by the remote host', None, 10054, None))

During handling of the above exception, another exception occurred:

Traceback (most recent call last):
  File "D:\Projects\RAG\frontend\app.py", line 32, in <module>
    response = requests.post(
               ^^^^^^^^^^^^^^
  File "C:\Users\harsh\miniconda3\Lib\site-packages\requests\api.py", line 115, in post
    return request("post", url, data=data, json=json, **kwargs)
           ^^^^^^^^^^^^^^^^^^^^^^^^^^^^^^^^^^^^^^^^^^^^^^^^^^^^
  File "C:\Users\harsh\miniconda3\Lib\site-packages\requests\api.py", line 59, in request
    return session.request(method=method, url=url, **kwargs)
           ^^^^^^^^^^^^^^^^^^^^^^^^^^^^^^^^^^^^^^^^^^^^^^^^^
  File "C:\Users\harsh\miniconda3\Lib\site-packages\requests\sessions.py", line 589, in request
    resp = self.send(prep, **send_kwargs)
           ^^^^^^^^^^^^^^^^^^^^^^^^^^^^^^
  File "C:\Users\harsh\miniconda3\Lib\site-packages\requests\sessions.py", line 703, in send
    r = adapter.send(request, **kwargs)
        ^^^^^^^^^^^^^^^^^^^^^^^^^^^^^^^
  File "C:\Users\harsh\miniconda3\Lib\site-packages\requests\adapters.py", line 682, in send
    raise ConnectionError(err, request=request)
requests.exceptions.ConnectionError: ('Connection aborted.', ConnectionResetError(10054, 'An existing connection was forcibly closed by the remote host', None, 10054, None))
An error occurred: HTTPConnectionPool(host='localhost', port=9000): Max retries exceeded with url: /api/ragas (Caused by NewConnectionError('<urllib3.connection.HTTPConnection object at 0x000001FA5BF7A300>: Failed to establish a new connection: [WinError 10061] No connection could be made because the target machine actively refused it'))
Traceback (most recent call last):
  File "C:\Users\harsh\miniconda3\Lib\site-packages\urllib3\connection.py", line 203, in _new_conn
    sock = connection.create_connection(
           ^^^^^^^^^^^^^^^^^^^^^^^^^^^^^
  File "C:\Users\harsh\miniconda3\Lib\site-packages\urllib3\util\connection.py", line 85, in create_connection
    raise err
  File "C:\Users\harsh\miniconda3\Lib\site-packages\urllib3\util\connection.py", line 73, in create_connection
    sock.connect(sa)
ConnectionRefusedError: [WinError 10061] No connection could be made because the target machine actively refused it

The above exception was the direct cause of the following exception:

Traceback (most recent call last):
  File "C:\Users\harsh\miniconda3\Lib\site-packages\urllib3\connectionpool.py", line 790, in urlopen
    response = self._make_request(
               ^^^^^^^^^^^^^^^^^^^
  File "C:\Users\harsh\miniconda3\Lib\site-packages\urllib3\connectionpool.py", line 496, in _make_request
    conn.request(
  File "C:\Users\harsh\miniconda3\Lib\site-packages\urllib3\connection.py", line 395, in request
    self.endheaders()
  File "C:\Users\harsh\miniconda3\Lib\http\client.py", line 1326, in endheaders
    self._send_output(message_body, encode_chunked=encode_chunked)
  File "C:\Users\harsh\miniconda3\Lib\http\client.py", line 1085, in _send_output
    self.send(msg)
  File "C:\Users\harsh\miniconda3\Lib\http\client.py", line 1029, in send
    self.connect()
  File "C:\Users\harsh\miniconda3\Lib\site-packages\urllib3\connection.py", line 243, in connect
    self.sock = self._new_conn()
                ^^^^^^^^^^^^^^^^
  File "C:\Users\harsh\miniconda3\Lib\site-packages\urllib3\connection.py", line 218, in _new_conn
    raise NewConnectionError(
urllib3.exceptions.NewConnectionError: <urllib3.connection.HTTPConnection object at 0x000001FA5BF7A300>: Failed to establish a new connection: [WinError 10061] No connection could be made because the target machine actively refused it

The above exception was the direct cause of the following exception:

Traceback (most recent call last):
  File "C:\Users\harsh\miniconda3\Lib\site-packages\requests\adapters.py", line 667, in send
    resp = conn.urlopen(
           ^^^^^^^^^^^^^
  File "C:\Users\harsh\miniconda3\Lib\site-packages\urllib3\connectionpool.py", line 844, in urlopen
    retries = retries.increment(
              ^^^^^^^^^^^^^^^^^^
  File "C:\Users\harsh\miniconda3\Lib\site-packages\urllib3\util\retry.py", line 515, in increment
    raise MaxRetryError(_pool, url, reason) from reason  # type: ignore[arg-type]
    ^^^^^^^^^^^^^^^^^^^^^^^^^^^^^^^^^^^^^^^^^^^^^^^^^^^
urllib3.exceptions.MaxRetryError: HTTPConnectionPool(host='localhost', port=9000): Max retries exceeded with url: /api/ragas (Caused by NewConnectionError('<urllib3.connection.HTTPConnection object at 0x000001FA5BF7A300>: Failed to establish a new connection: [WinError 10061] No connection could be made because the target machine actively refused it'))

During handling of the above exception, another exception occurred:

Traceback (most recent call last):
  File "D:\Projects\RAG\frontend\app.py", line 32, in <module>
    response = requests.post(
               ^^^^^^^^^^^^^^
  File "C:\Users\harsh\miniconda3\Lib\site-packages\requests\api.py", line 115, in post
    return request("post", url, data=data, json=json, **kwargs)
           ^^^^^^^^^^^^^^^^^^^^^^^^^^^^^^^^^^^^^^^^^^^^^^^^^^^^
  File "C:\Users\harsh\miniconda3\Lib\site-packages\requests\api.py", line 59, in request
    return session.request(method=method, url=url, **kwargs)
           ^^^^^^^^^^^^^^^^^^^^^^^^^^^^^^^^^^^^^^^^^^^^^^^^^
  File "C:\Users\harsh\miniconda3\Lib\site-packages\requests\sessions.py", line 589, in request
    resp = self.send(prep, **send_kwargs)
           ^^^^^^^^^^^^^^^^^^^^^^^^^^^^^^
  File "C:\Users\harsh\miniconda3\Lib\site-packages\requests\sessions.py", line 703, in send
    r = adapter.send(request, **kwargs)
        ^^^^^^^^^^^^^^^^^^^^^^^^^^^^^^^
  File "C:\Users\harsh\miniconda3\Lib\site-packages\requests\adapters.py", line 700, in send
    raise ConnectionError(e, request=request)
requests.exceptions.ConnectionError: HTTPConnectionPool(host='localhost', port=9000): Max retries exceeded with url: /api/ragas (Caused by NewConnectionError('<urllib3.connection.HTTPConnection object at 0x000001FA5BF7A300>: Failed to establish a new connection: [WinError 10061] No connection could be made because the target machine actively refused it'))
Request sent to FastAPI backend.
Successful response received from FastAPI backend.
Request sent to FastAPI backend.
Successful response received from FastAPI backend.
Request sent to FastAPI backend.
Successful response received from FastAPI backend.
Request sent to FastAPI backend.
Successful response received from FastAPI backend.
Request sent to FastAPI backend.
Successful response received from FastAPI backend.
Request sent to FastAPI backend.
Successful response received from FastAPI backend.
Request sent to FastAPI backend.
Successful response received from FastAPI backend.
Request sent to FastAPI backend.
Successful response received from FastAPI backend.
Request sent to FastAPI backend.
Successful response received from FastAPI backend.
Request sent to FastAPI backend.
Successful response received from FastAPI backend.
Request sent to FastAPI backend.
Successful response received from FastAPI backend.
Request sent to FastAPI backend.
Successful response received from FastAPI backend.
Request sent to FastAPI backend.
Successful response received from FastAPI backend.
Request sent to FastAPI backend.
Successful response received from FastAPI backend.
Request sent to FastAPI backend.
Successful response received from FastAPI backend.
Request sent to FastAPI backend.
Successful response received from FastAPI backend.
Request sent to FastAPI backend.
Successful response received from FastAPI backend.
Request sent to FastAPI backend.
Successful response received from FastAPI backend.
Request sent to FastAPI backend.
Successful response received from FastAPI backend.
Request sent to FastAPI backend.
Successful response received from FastAPI backend.
No PDF was uploaded by the user.
Request sent to FastAPI backend.
Successful response received from FastAPI backend.
Request sent to FastAPI backend.
Successful response received from FastAPI backend.
Request sent to FastAPI backend.
Successful response received from FastAPI backend.
Request sent to FastAPI backend.
Successful response received from FastAPI backend.
Request sent to FastAPI backend.
Successful response received from FastAPI backend.
Request sent to FastAPI backend.
Successful response received from FastAPI backend.
Request sent to FastAPI backend.
Successful response received from FastAPI backend.
Request sent to FastAPI backend.
Successful response received from FastAPI backend.
Request sent to FastAPI backend.
Successful response received from FastAPI backend.
Request sent to FastAPI backend.
Successful response received from FastAPI backend.
Request sent to FastAPI backend.
Successful response received from FastAPI backend.
Request sent to FastAPI backend.
Successful response received from FastAPI backend.
Request sent to FastAPI backend.
Successful response received from FastAPI backend.
Request sent to FastAPI backend.
Successful response received from FastAPI backend.
Request sent to FastAPI backend.
Successful response received from FastAPI backend.
Request sent to FastAPI backend.
Successful response received from FastAPI backend.
Request sent to FastAPI backend.
Successful response received from FastAPI backend.
Request sent to FastAPI backend.
Successful response received from FastAPI backend.
Request sent to FastAPI backend.
Successful response received from FastAPI backend.
An error occurred: HTTPConnectionPool(host='localhost', port=9000): Max retries exceeded with url: /api/ragas (Caused by NewConnectionError('<urllib3.connection.HTTPConnection object at 0x0000022A1DF67080>: Failed to establish a new connection: [WinError 10061] No connection could be made because the target machine actively refused it'))
Traceback (most recent call last):
  File "C:\Users\harsh\miniconda3\Lib\site-packages\urllib3\connection.py", line 203, in _new_conn
    sock = connection.create_connection(
           ^^^^^^^^^^^^^^^^^^^^^^^^^^^^^
  File "C:\Users\harsh\miniconda3\Lib\site-packages\urllib3\util\connection.py", line 85, in create_connection
    raise err
  File "C:\Users\harsh\miniconda3\Lib\site-packages\urllib3\util\connection.py", line 73, in create_connection
    sock.connect(sa)
ConnectionRefusedError: [WinError 10061] No connection could be made because the target machine actively refused it

The above exception was the direct cause of the following exception:

Traceback (most recent call last):
  File "C:\Users\harsh\miniconda3\Lib\site-packages\urllib3\connectionpool.py", line 790, in urlopen
    response = self._make_request(
               ^^^^^^^^^^^^^^^^^^^
  File "C:\Users\harsh\miniconda3\Lib\site-packages\urllib3\connectionpool.py", line 496, in _make_request
    conn.request(
  File "C:\Users\harsh\miniconda3\Lib\site-packages\urllib3\connection.py", line 395, in request
    self.endheaders()
  File "C:\Users\harsh\miniconda3\Lib\http\client.py", line 1326, in endheaders
    self._send_output(message_body, encode_chunked=encode_chunked)
  File "C:\Users\harsh\miniconda3\Lib\http\client.py", line 1085, in _send_output
    self.send(msg)
  File "C:\Users\harsh\miniconda3\Lib\http\client.py", line 1029, in send
    self.connect()
  File "C:\Users\harsh\miniconda3\Lib\site-packages\urllib3\connection.py", line 243, in connect
    self.sock = self._new_conn()
                ^^^^^^^^^^^^^^^^
  File "C:\Users\harsh\miniconda3\Lib\site-packages\urllib3\connection.py", line 218, in _new_conn
    raise NewConnectionError(
urllib3.exceptions.NewConnectionError: <urllib3.connection.HTTPConnection object at 0x0000022A1DF67080>: Failed to establish a new connection: [WinError 10061] No connection could be made because the target machine actively refused it

The above exception was the direct cause of the following exception:

Traceback (most recent call last):
  File "C:\Users\harsh\miniconda3\Lib\site-packages\requests\adapters.py", line 667, in send
    resp = conn.urlopen(
           ^^^^^^^^^^^^^
  File "C:\Users\harsh\miniconda3\Lib\site-packages\urllib3\connectionpool.py", line 844, in urlopen
    retries = retries.increment(
              ^^^^^^^^^^^^^^^^^^
  File "C:\Users\harsh\miniconda3\Lib\site-packages\urllib3\util\retry.py", line 515, in increment
    raise MaxRetryError(_pool, url, reason) from reason  # type: ignore[arg-type]
    ^^^^^^^^^^^^^^^^^^^^^^^^^^^^^^^^^^^^^^^^^^^^^^^^^^^
urllib3.exceptions.MaxRetryError: HTTPConnectionPool(host='localhost', port=9000): Max retries exceeded with url: /api/ragas (Caused by NewConnectionError('<urllib3.connection.HTTPConnection object at 0x0000022A1DF67080>: Failed to establish a new connection: [WinError 10061] No connection could be made because the target machine actively refused it'))

During handling of the above exception, another exception occurred:

Traceback (most recent call last):
  File "D:\Projects\RAG\frontend\app.py", line 32, in <module>
    response = requests.post(
               ^^^^^^^^^^^^^^
  File "C:\Users\harsh\miniconda3\Lib\site-packages\requests\api.py", line 115, in post
    return request("post", url, data=data, json=json, **kwargs)
           ^^^^^^^^^^^^^^^^^^^^^^^^^^^^^^^^^^^^^^^^^^^^^^^^^^^^
  File "C:\Users\harsh\miniconda3\Lib\site-packages\requests\api.py", line 59, in request
    return session.request(method=method, url=url, **kwargs)
           ^^^^^^^^^^^^^^^^^^^^^^^^^^^^^^^^^^^^^^^^^^^^^^^^^
  File "C:\Users\harsh\miniconda3\Lib\site-packages\requests\sessions.py", line 589, in request
    resp = self.send(prep, **send_kwargs)
           ^^^^^^^^^^^^^^^^^^^^^^^^^^^^^^
  File "C:\Users\harsh\miniconda3\Lib\site-packages\requests\sessions.py", line 703, in send
    r = adapter.send(request, **kwargs)
        ^^^^^^^^^^^^^^^^^^^^^^^^^^^^^^^
  File "C:\Users\harsh\miniconda3\Lib\site-packages\requests\adapters.py", line 700, in send
    raise ConnectionError(e, request=request)
requests.exceptions.ConnectionError: HTTPConnectionPool(host='localhost', port=9000): Max retries exceeded with url: /api/ragas (Caused by NewConnectionError('<urllib3.connection.HTTPConnection object at 0x0000022A1DF67080>: Failed to establish a new connection: [WinError 10061] No connection could be made because the target machine actively refused it'))
Request sent to FastAPI backend.
Successful response received from FastAPI backend.
Request sent to FastAPI backend.
Successful response received from FastAPI backend.
Request sent to FastAPI backend.
Successful response received from FastAPI backend.
Request sent to FastAPI backend.
Successful response received from FastAPI backend.
Request sent to FastAPI backend.
Successful response received from FastAPI backend.
Request sent to FastAPI backend.
Successful response received from FastAPI backend.
Request sent to FastAPI backend.
Successful response received from FastAPI backend.
Request sent to FastAPI backend.
Successful response received from FastAPI backend.
Request sent to FastAPI backend.
Successful response received from FastAPI backend.
Request sent to FastAPI backend.
Successful response received from FastAPI backend.
Request sent to FastAPI backend.
Successful response received from FastAPI backend.
Request sent to FastAPI backend.
Successful response received from FastAPI backend.
An error occurred: HTTPConnectionPool(host='localhost', port=9000): Max retries exceeded with url: /api/ragas (Caused by NewConnectionError('<urllib3.connection.HTTPConnection object at 0x000002E0467EF1A0>: Failed to establish a new connection: [WinError 10061] No connection could be made because the target machine actively refused it'))
Traceback (most recent call last):
  File "C:\Users\harsh\miniconda3\Lib\site-packages\urllib3\connection.py", line 203, in _new_conn
    sock = connection.create_connection(
           ^^^^^^^^^^^^^^^^^^^^^^^^^^^^^
  File "C:\Users\harsh\miniconda3\Lib\site-packages\urllib3\util\connection.py", line 85, in create_connection
    raise err
  File "C:\Users\harsh\miniconda3\Lib\site-packages\urllib3\util\connection.py", line 73, in create_connection
    sock.connect(sa)
ConnectionRefusedError: [WinError 10061] No connection could be made because the target machine actively refused it

The above exception was the direct cause of the following exception:

Traceback (most recent call last):
  File "C:\Users\harsh\miniconda3\Lib\site-packages\urllib3\connectionpool.py", line 790, in urlopen
    response = self._make_request(
               ^^^^^^^^^^^^^^^^^^^
  File "C:\Users\harsh\miniconda3\Lib\site-packages\urllib3\connectionpool.py", line 496, in _make_request
    conn.request(
  File "C:\Users\harsh\miniconda3\Lib\site-packages\urllib3\connection.py", line 395, in request
    self.endheaders()
  File "C:\Users\harsh\miniconda3\Lib\http\client.py", line 1326, in endheaders
    self._send_output(message_body, encode_chunked=encode_chunked)
  File "C:\Users\harsh\miniconda3\Lib\http\client.py", line 1085, in _send_output
    self.send(msg)
  File "C:\Users\harsh\miniconda3\Lib\http\client.py", line 1029, in send
    self.connect()
  File "C:\Users\harsh\miniconda3\Lib\site-packages\urllib3\connection.py", line 243, in connect
    self.sock = self._new_conn()
                ^^^^^^^^^^^^^^^^
  File "C:\Users\harsh\miniconda3\Lib\site-packages\urllib3\connection.py", line 218, in _new_conn
    raise NewConnectionError(
urllib3.exceptions.NewConnectionError: <urllib3.connection.HTTPConnection object at 0x000002E0467EF1A0>: Failed to establish a new connection: [WinError 10061] No connection could be made because the target machine actively refused it

The above exception was the direct cause of the following exception:

Traceback (most recent call last):
  File "C:\Users\harsh\miniconda3\Lib\site-packages\requests\adapters.py", line 667, in send
    resp = conn.urlopen(
           ^^^^^^^^^^^^^
  File "C:\Users\harsh\miniconda3\Lib\site-packages\urllib3\connectionpool.py", line 844, in urlopen
    retries = retries.increment(
              ^^^^^^^^^^^^^^^^^^
  File "C:\Users\harsh\miniconda3\Lib\site-packages\urllib3\util\retry.py", line 515, in increment
    raise MaxRetryError(_pool, url, reason) from reason  # type: ignore[arg-type]
    ^^^^^^^^^^^^^^^^^^^^^^^^^^^^^^^^^^^^^^^^^^^^^^^^^^^
urllib3.exceptions.MaxRetryError: HTTPConnectionPool(host='localhost', port=9000): Max retries exceeded with url: /api/ragas (Caused by NewConnectionError('<urllib3.connection.HTTPConnection object at 0x000002E0467EF1A0>: Failed to establish a new connection: [WinError 10061] No connection could be made because the target machine actively refused it'))

During handling of the above exception, another exception occurred:

Traceback (most recent call last):
  File "D:\Projects\RAG\frontend\app.py", line 32, in <module>
    response = requests.post(
               ^^^^^^^^^^^^^^
  File "C:\Users\harsh\miniconda3\Lib\site-packages\requests\api.py", line 115, in post
    return request("post", url, data=data, json=json, **kwargs)
           ^^^^^^^^^^^^^^^^^^^^^^^^^^^^^^^^^^^^^^^^^^^^^^^^^^^^
  File "C:\Users\harsh\miniconda3\Lib\site-packages\requests\api.py", line 59, in request
    return session.request(method=method, url=url, **kwargs)
           ^^^^^^^^^^^^^^^^^^^^^^^^^^^^^^^^^^^^^^^^^^^^^^^^^
  File "C:\Users\harsh\miniconda3\Lib\site-packages\requests\sessions.py", line 589, in request
    resp = self.send(prep, **send_kwargs)
           ^^^^^^^^^^^^^^^^^^^^^^^^^^^^^^
  File "C:\Users\harsh\miniconda3\Lib\site-packages\requests\sessions.py", line 703, in send
    r = adapter.send(request, **kwargs)
        ^^^^^^^^^^^^^^^^^^^^^^^^^^^^^^^
  File "C:\Users\harsh\miniconda3\Lib\site-packages\requests\adapters.py", line 700, in send
    raise ConnectionError(e, request=request)
requests.exceptions.ConnectionError: HTTPConnectionPool(host='localhost', port=9000): Max retries exceeded with url: /api/ragas (Caused by NewConnectionError('<urllib3.connection.HTTPConnection object at 0x000002E0467EF1A0>: Failed to establish a new connection: [WinError 10061] No connection could be made because the target machine actively refused it'))
Request sent to FastAPI backend.
Successful response received from FastAPI backend.
Request sent to FastAPI backend.
Successful response received from FastAPI backend.
Request sent to FastAPI backend.
Successful response received from FastAPI backend.
An error occurred: HTTPConnectionPool(host='localhost', port=9000): Max retries exceeded with url: /api/ragas (Caused by NewConnectionError('<urllib3.connection.HTTPConnection object at 0x000002E0467EE3F0>: Failed to establish a new connection: [WinError 10061] No connection could be made because the target machine actively refused it'))
Traceback (most recent call last):
  File "C:\Users\harsh\miniconda3\Lib\site-packages\urllib3\connection.py", line 203, in _new_conn
    sock = connection.create_connection(
           ^^^^^^^^^^^^^^^^^^^^^^^^^^^^^
  File "C:\Users\harsh\miniconda3\Lib\site-packages\urllib3\util\connection.py", line 85, in create_connection
    raise err
  File "C:\Users\harsh\miniconda3\Lib\site-packages\urllib3\util\connection.py", line 73, in create_connection
    sock.connect(sa)
ConnectionRefusedError: [WinError 10061] No connection could be made because the target machine actively refused it

The above exception was the direct cause of the following exception:

Traceback (most recent call last):
  File "C:\Users\harsh\miniconda3\Lib\site-packages\urllib3\connectionpool.py", line 790, in urlopen
    response = self._make_request(
               ^^^^^^^^^^^^^^^^^^^
  File "C:\Users\harsh\miniconda3\Lib\site-packages\urllib3\connectionpool.py", line 496, in _make_request
    conn.request(
  File "C:\Users\harsh\miniconda3\Lib\site-packages\urllib3\connection.py", line 395, in request
    self.endheaders()
  File "C:\Users\harsh\miniconda3\Lib\http\client.py", line 1326, in endheaders
    self._send_output(message_body, encode_chunked=encode_chunked)
  File "C:\Users\harsh\miniconda3\Lib\http\client.py", line 1085, in _send_output
    self.send(msg)
  File "C:\Users\harsh\miniconda3\Lib\http\client.py", line 1029, in send
    self.connect()
  File "C:\Users\harsh\miniconda3\Lib\site-packages\urllib3\connection.py", line 243, in connect
    self.sock = self._new_conn()
                ^^^^^^^^^^^^^^^^
  File "C:\Users\harsh\miniconda3\Lib\site-packages\urllib3\connection.py", line 218, in _new_conn
    raise NewConnectionError(
urllib3.exceptions.NewConnectionError: <urllib3.connection.HTTPConnection object at 0x000002E0467EE3F0>: Failed to establish a new connection: [WinError 10061] No connection could be made because the target machine actively refused it

The above exception was the direct cause of the following exception:

Traceback (most recent call last):
  File "C:\Users\harsh\miniconda3\Lib\site-packages\requests\adapters.py", line 667, in send
    resp = conn.urlopen(
           ^^^^^^^^^^^^^
  File "C:\Users\harsh\miniconda3\Lib\site-packages\urllib3\connectionpool.py", line 844, in urlopen
    retries = retries.increment(
              ^^^^^^^^^^^^^^^^^^
  File "C:\Users\harsh\miniconda3\Lib\site-packages\urllib3\util\retry.py", line 515, in increment
    raise MaxRetryError(_pool, url, reason) from reason  # type: ignore[arg-type]
    ^^^^^^^^^^^^^^^^^^^^^^^^^^^^^^^^^^^^^^^^^^^^^^^^^^^
urllib3.exceptions.MaxRetryError: HTTPConnectionPool(host='localhost', port=9000): Max retries exceeded with url: /api/ragas (Caused by NewConnectionError('<urllib3.connection.HTTPConnection object at 0x000002E0467EE3F0>: Failed to establish a new connection: [WinError 10061] No connection could be made because the target machine actively refused it'))

During handling of the above exception, another exception occurred:

Traceback (most recent call last):
  File "D:\Projects\RAG\frontend\app.py", line 32, in <module>
    response = requests.post(
               ^^^^^^^^^^^^^^
  File "C:\Users\harsh\miniconda3\Lib\site-packages\requests\api.py", line 115, in post
    return request("post", url, data=data, json=json, **kwargs)
           ^^^^^^^^^^^^^^^^^^^^^^^^^^^^^^^^^^^^^^^^^^^^^^^^^^^^
  File "C:\Users\harsh\miniconda3\Lib\site-packages\requests\api.py", line 59, in request
    return session.request(method=method, url=url, **kwargs)
           ^^^^^^^^^^^^^^^^^^^^^^^^^^^^^^^^^^^^^^^^^^^^^^^^^
  File "C:\Users\harsh\miniconda3\Lib\site-packages\requests\sessions.py", line 589, in request
    resp = self.send(prep, **send_kwargs)
           ^^^^^^^^^^^^^^^^^^^^^^^^^^^^^^
  File "C:\Users\harsh\miniconda3\Lib\site-packages\requests\sessions.py", line 703, in send
    r = adapter.send(request, **kwargs)
        ^^^^^^^^^^^^^^^^^^^^^^^^^^^^^^^
  File "C:\Users\harsh\miniconda3\Lib\site-packages\requests\adapters.py", line 700, in send
    raise ConnectionError(e, request=request)
requests.exceptions.ConnectionError: HTTPConnectionPool(host='localhost', port=9000): Max retries exceeded with url: /api/ragas (Caused by NewConnectionError('<urllib3.connection.HTTPConnection object at 0x000002E0467EE3F0>: Failed to establish a new connection: [WinError 10061] No connection could be made because the target machine actively refused it'))
Request sent to FastAPI backend.
Successful response received from FastAPI backend.
Request sent to FastAPI backend.
Successful response received from FastAPI backend.
Request sent to FastAPI backend.
Successful response received from FastAPI backend.
Request sent to FastAPI backend.
Successful response received from FastAPI backend.
Request sent to FastAPI backend.
Successful response received from FastAPI backend.
Request sent to FastAPI backend.
Successful response received from FastAPI backend.
Request sent to FastAPI backend.
Successful response received from FastAPI backend.
Request sent to FastAPI backend.
Successful response received from FastAPI backend.
An error occurred: HTTPConnectionPool(host='localhost', port=9000): Max retries exceeded with url: /api/ragas (Caused by NewConnectionError('<urllib3.connection.HTTPConnection object at 0x00000216B56CCBC0>: Failed to establish a new connection: [WinError 10061] No connection could be made because the target machine actively refused it'))
Traceback (most recent call last):
  File "C:\Users\harsh\miniconda3\Lib\site-packages\urllib3\connection.py", line 203, in _new_conn
    sock = connection.create_connection(
           ^^^^^^^^^^^^^^^^^^^^^^^^^^^^^
  File "C:\Users\harsh\miniconda3\Lib\site-packages\urllib3\util\connection.py", line 85, in create_connection
    raise err
  File "C:\Users\harsh\miniconda3\Lib\site-packages\urllib3\util\connection.py", line 73, in create_connection
    sock.connect(sa)
ConnectionRefusedError: [WinError 10061] No connection could be made because the target machine actively refused it

The above exception was the direct cause of the following exception:

Traceback (most recent call last):
  File "C:\Users\harsh\miniconda3\Lib\site-packages\urllib3\connectionpool.py", line 790, in urlopen
    response = self._make_request(
               ^^^^^^^^^^^^^^^^^^^
  File "C:\Users\harsh\miniconda3\Lib\site-packages\urllib3\connectionpool.py", line 496, in _make_request
    conn.request(
  File "C:\Users\harsh\miniconda3\Lib\site-packages\urllib3\connection.py", line 395, in request
    self.endheaders()
  File "C:\Users\harsh\miniconda3\Lib\http\client.py", line 1326, in endheaders
    self._send_output(message_body, encode_chunked=encode_chunked)
  File "C:\Users\harsh\miniconda3\Lib\http\client.py", line 1085, in _send_output
    self.send(msg)
  File "C:\Users\harsh\miniconda3\Lib\http\client.py", line 1029, in send
    self.connect()
  File "C:\Users\harsh\miniconda3\Lib\site-packages\urllib3\connection.py", line 243, in connect
    self.sock = self._new_conn()
                ^^^^^^^^^^^^^^^^
  File "C:\Users\harsh\miniconda3\Lib\site-packages\urllib3\connection.py", line 218, in _new_conn
    raise NewConnectionError(
urllib3.exceptions.NewConnectionError: <urllib3.connection.HTTPConnection object at 0x00000216B56CCBC0>: Failed to establish a new connection: [WinError 10061] No connection could be made because the target machine actively refused it

The above exception was the direct cause of the following exception:

Traceback (most recent call last):
  File "C:\Users\harsh\miniconda3\Lib\site-packages\requests\adapters.py", line 667, in send
    resp = conn.urlopen(
           ^^^^^^^^^^^^^
  File "C:\Users\harsh\miniconda3\Lib\site-packages\urllib3\connectionpool.py", line 844, in urlopen
    retries = retries.increment(
              ^^^^^^^^^^^^^^^^^^
  File "C:\Users\harsh\miniconda3\Lib\site-packages\urllib3\util\retry.py", line 515, in increment
    raise MaxRetryError(_pool, url, reason) from reason  # type: ignore[arg-type]
    ^^^^^^^^^^^^^^^^^^^^^^^^^^^^^^^^^^^^^^^^^^^^^^^^^^^
urllib3.exceptions.MaxRetryError: HTTPConnectionPool(host='localhost', port=9000): Max retries exceeded with url: /api/ragas (Caused by NewConnectionError('<urllib3.connection.HTTPConnection object at 0x00000216B56CCBC0>: Failed to establish a new connection: [WinError 10061] No connection could be made because the target machine actively refused it'))

During handling of the above exception, another exception occurred:

Traceback (most recent call last):
  File "D:\Projects\RAG\frontend\app.py", line 32, in <module>
    response = requests.post(
               ^^^^^^^^^^^^^^
  File "C:\Users\harsh\miniconda3\Lib\site-packages\requests\api.py", line 115, in post
    return request("post", url, data=data, json=json, **kwargs)
           ^^^^^^^^^^^^^^^^^^^^^^^^^^^^^^^^^^^^^^^^^^^^^^^^^^^^
  File "C:\Users\harsh\miniconda3\Lib\site-packages\requests\api.py", line 59, in request
    return session.request(method=method, url=url, **kwargs)
           ^^^^^^^^^^^^^^^^^^^^^^^^^^^^^^^^^^^^^^^^^^^^^^^^^
  File "C:\Users\harsh\miniconda3\Lib\site-packages\requests\sessions.py", line 589, in request
    resp = self.send(prep, **send_kwargs)
           ^^^^^^^^^^^^^^^^^^^^^^^^^^^^^^
  File "C:\Users\harsh\miniconda3\Lib\site-packages\requests\sessions.py", line 703, in send
    r = adapter.send(request, **kwargs)
        ^^^^^^^^^^^^^^^^^^^^^^^^^^^^^^^
  File "C:\Users\harsh\miniconda3\Lib\site-packages\requests\adapters.py", line 700, in send
    raise ConnectionError(e, request=request)
requests.exceptions.ConnectionError: HTTPConnectionPool(host='localhost', port=9000): Max retries exceeded with url: /api/ragas (Caused by NewConnectionError('<urllib3.connection.HTTPConnection object at 0x00000216B56CCBC0>: Failed to establish a new connection: [WinError 10061] No connection could be made because the target machine actively refused it'))
Request sent to FastAPI backend.
Successful response received from FastAPI backend.
Request sent to FastAPI backend.
Successful response received from FastAPI backend.
An error occurred: ('Connection aborted.', ConnectionResetError(10054, 'An existing connection was forcibly closed by the remote host', None, 10054, None))
Traceback (most recent call last):
  File "C:\Users\harsh\miniconda3\Lib\site-packages\urllib3\connectionpool.py", line 790, in urlopen
    response = self._make_request(
               ^^^^^^^^^^^^^^^^^^^
  File "C:\Users\harsh\miniconda3\Lib\site-packages\urllib3\connectionpool.py", line 536, in _make_request
    response = conn.getresponse()
               ^^^^^^^^^^^^^^^^^^
  File "C:\Users\harsh\miniconda3\Lib\site-packages\urllib3\connection.py", line 461, in getresponse
    httplib_response = super().getresponse()
                       ^^^^^^^^^^^^^^^^^^^^^
  File "C:\Users\harsh\miniconda3\Lib\http\client.py", line 1423, in getresponse
    response.begin()
  File "C:\Users\harsh\miniconda3\Lib\http\client.py", line 331, in begin
    version, status, reason = self._read_status()
                              ^^^^^^^^^^^^^^^^^^^
  File "C:\Users\harsh\miniconda3\Lib\http\client.py", line 292, in _read_status
    line = str(self.fp.readline(_MAXLINE + 1), "iso-8859-1")
               ^^^^^^^^^^^^^^^^^^^^^^^^^^^^^^
  File "C:\Users\harsh\miniconda3\Lib\socket.py", line 707, in readinto
    return self._sock.recv_into(b)
           ^^^^^^^^^^^^^^^^^^^^^^^
ConnectionResetError: [WinError 10054] An existing connection was forcibly closed by the remote host

During handling of the above exception, another exception occurred:

Traceback (most recent call last):
  File "C:\Users\harsh\miniconda3\Lib\site-packages\requests\adapters.py", line 667, in send
    resp = conn.urlopen(
           ^^^^^^^^^^^^^
  File "C:\Users\harsh\miniconda3\Lib\site-packages\urllib3\connectionpool.py", line 844, in urlopen
    retries = retries.increment(
              ^^^^^^^^^^^^^^^^^^
  File "C:\Users\harsh\miniconda3\Lib\site-packages\urllib3\util\retry.py", line 470, in increment
    raise reraise(type(error), error, _stacktrace)
          ^^^^^^^^^^^^^^^^^^^^^^^^^^^^^^^^^^^^^^^^
  File "C:\Users\harsh\miniconda3\Lib\site-packages\urllib3\util\util.py", line 38, in reraise
    raise value.with_traceback(tb)
  File "C:\Users\harsh\miniconda3\Lib\site-packages\urllib3\connectionpool.py", line 790, in urlopen
    response = self._make_request(
               ^^^^^^^^^^^^^^^^^^^
  File "C:\Users\harsh\miniconda3\Lib\site-packages\urllib3\connectionpool.py", line 536, in _make_request
    response = conn.getresponse()
               ^^^^^^^^^^^^^^^^^^
  File "C:\Users\harsh\miniconda3\Lib\site-packages\urllib3\connection.py", line 461, in getresponse
    httplib_response = super().getresponse()
                       ^^^^^^^^^^^^^^^^^^^^^
  File "C:\Users\harsh\miniconda3\Lib\http\client.py", line 1423, in getresponse
    response.begin()
  File "C:\Users\harsh\miniconda3\Lib\http\client.py", line 331, in begin
    version, status, reason = self._read_status()
                              ^^^^^^^^^^^^^^^^^^^
  File "C:\Users\harsh\miniconda3\Lib\http\client.py", line 292, in _read_status
    line = str(self.fp.readline(_MAXLINE + 1), "iso-8859-1")
               ^^^^^^^^^^^^^^^^^^^^^^^^^^^^^^
  File "C:\Users\harsh\miniconda3\Lib\socket.py", line 707, in readinto
    return self._sock.recv_into(b)
           ^^^^^^^^^^^^^^^^^^^^^^^
urllib3.exceptions.ProtocolError: ('Connection aborted.', ConnectionResetError(10054, 'An existing connection was forcibly closed by the remote host', None, 10054, None))

During handling of the above exception, another exception occurred:

Traceback (most recent call last):
  File "D:\Projects\RAG\frontend\app.py", line 32, in <module>
    response = requests.post(
               ^^^^^^^^^^^^^^
  File "C:\Users\harsh\miniconda3\Lib\site-packages\requests\api.py", line 115, in post
    return request("post", url, data=data, json=json, **kwargs)
           ^^^^^^^^^^^^^^^^^^^^^^^^^^^^^^^^^^^^^^^^^^^^^^^^^^^^
  File "C:\Users\harsh\miniconda3\Lib\site-packages\requests\api.py", line 59, in request
    return session.request(method=method, url=url, **kwargs)
           ^^^^^^^^^^^^^^^^^^^^^^^^^^^^^^^^^^^^^^^^^^^^^^^^^
  File "C:\Users\harsh\miniconda3\Lib\site-packages\requests\sessions.py", line 589, in request
    resp = self.send(prep, **send_kwargs)
           ^^^^^^^^^^^^^^^^^^^^^^^^^^^^^^
  File "C:\Users\harsh\miniconda3\Lib\site-packages\requests\sessions.py", line 703, in send
    r = adapter.send(request, **kwargs)
        ^^^^^^^^^^^^^^^^^^^^^^^^^^^^^^^
  File "C:\Users\harsh\miniconda3\Lib\site-packages\requests\adapters.py", line 682, in send
    raise ConnectionError(err, request=request)
requests.exceptions.ConnectionError: ('Connection aborted.', ConnectionResetError(10054, 'An existing connection was forcibly closed by the remote host', None, 10054, None))
Request sent to FastAPI backend.
Successful response received from FastAPI backend.
Request sent to FastAPI backend.
Successful response received from FastAPI backend.
Request sent to FastAPI backend.
Successful response received from FastAPI backend.
Request sent to FastAPI backend.
Successful response received from FastAPI backend.
Request sent to FastAPI backend.
Successful response received from FastAPI backend.
Request sent to FastAPI backend.
Successful response received from FastAPI backend.
Request sent to FastAPI backend.
Successful response received from FastAPI backend.
Request sent to FastAPI backend.
Successful response received from FastAPI backend.
Request sent to FastAPI backend.
Successful response received from FastAPI backend.
Request sent to FastAPI backend.
Successful response received from FastAPI backend.
Request sent to FastAPI backend.
Successful response received from FastAPI backend.
Request sent to FastAPI backend.
Successful response received from FastAPI backend.
Request sent to FastAPI backend.
Successful response received from FastAPI backend.
Request sent to FastAPI backend.
Successful response received from FastAPI backend.
Request sent to FastAPI backend.
Successful response received from FastAPI backend.
Request sent to FastAPI backend.
Successful response received from FastAPI backend.
Request sent to FastAPI backend.
Successful response received from FastAPI backend.
Request sent to FastAPI backend.
Successful response received from FastAPI backend.
Request sent to FastAPI backend.
Successful response received from FastAPI backend.
Request sent to FastAPI backend.
Successful response received from FastAPI backend.
Request sent to FastAPI backend.
Successful response received from FastAPI backend.
Request sent to FastAPI backend.
Successful response received from FastAPI backend.
Request sent to FastAPI backend.
Successful response received from FastAPI backend.
An error occurred: ('Connection aborted.', ConnectionResetError(10054, 'An existing connection was forcibly closed by the remote host', None, 10054, None))
Traceback (most recent call last):
  File "C:\Users\harsh\miniconda3\Lib\site-packages\urllib3\connectionpool.py", line 790, in urlopen
    response = self._make_request(
               ^^^^^^^^^^^^^^^^^^^
  File "C:\Users\harsh\miniconda3\Lib\site-packages\urllib3\connectionpool.py", line 536, in _make_request
    response = conn.getresponse()
               ^^^^^^^^^^^^^^^^^^
  File "C:\Users\harsh\miniconda3\Lib\site-packages\urllib3\connection.py", line 461, in getresponse
    httplib_response = super().getresponse()
                       ^^^^^^^^^^^^^^^^^^^^^
  File "C:\Users\harsh\miniconda3\Lib\http\client.py", line 1423, in getresponse
    response.begin()
  File "C:\Users\harsh\miniconda3\Lib\http\client.py", line 331, in begin
    version, status, reason = self._read_status()
                              ^^^^^^^^^^^^^^^^^^^
  File "C:\Users\harsh\miniconda3\Lib\http\client.py", line 292, in _read_status
    line = str(self.fp.readline(_MAXLINE + 1), "iso-8859-1")
               ^^^^^^^^^^^^^^^^^^^^^^^^^^^^^^
  File "C:\Users\harsh\miniconda3\Lib\socket.py", line 707, in readinto
    return self._sock.recv_into(b)
           ^^^^^^^^^^^^^^^^^^^^^^^
ConnectionResetError: [WinError 10054] An existing connection was forcibly closed by the remote host

During handling of the above exception, another exception occurred:

Traceback (most recent call last):
  File "C:\Users\harsh\miniconda3\Lib\site-packages\requests\adapters.py", line 667, in send
    resp = conn.urlopen(
           ^^^^^^^^^^^^^
  File "C:\Users\harsh\miniconda3\Lib\site-packages\urllib3\connectionpool.py", line 844, in urlopen
    retries = retries.increment(
              ^^^^^^^^^^^^^^^^^^
  File "C:\Users\harsh\miniconda3\Lib\site-packages\urllib3\util\retry.py", line 470, in increment
    raise reraise(type(error), error, _stacktrace)
          ^^^^^^^^^^^^^^^^^^^^^^^^^^^^^^^^^^^^^^^^
  File "C:\Users\harsh\miniconda3\Lib\site-packages\urllib3\util\util.py", line 38, in reraise
    raise value.with_traceback(tb)
  File "C:\Users\harsh\miniconda3\Lib\site-packages\urllib3\connectionpool.py", line 790, in urlopen
    response = self._make_request(
               ^^^^^^^^^^^^^^^^^^^
  File "C:\Users\harsh\miniconda3\Lib\site-packages\urllib3\connectionpool.py", line 536, in _make_request
    response = conn.getresponse()
               ^^^^^^^^^^^^^^^^^^
  File "C:\Users\harsh\miniconda3\Lib\site-packages\urllib3\connection.py", line 461, in getresponse
    httplib_response = super().getresponse()
                       ^^^^^^^^^^^^^^^^^^^^^
  File "C:\Users\harsh\miniconda3\Lib\http\client.py", line 1423, in getresponse
    response.begin()
  File "C:\Users\harsh\miniconda3\Lib\http\client.py", line 331, in begin
    version, status, reason = self._read_status()
                              ^^^^^^^^^^^^^^^^^^^
  File "C:\Users\harsh\miniconda3\Lib\http\client.py", line 292, in _read_status
    line = str(self.fp.readline(_MAXLINE + 1), "iso-8859-1")
               ^^^^^^^^^^^^^^^^^^^^^^^^^^^^^^
  File "C:\Users\harsh\miniconda3\Lib\socket.py", line 707, in readinto
    return self._sock.recv_into(b)
           ^^^^^^^^^^^^^^^^^^^^^^^
urllib3.exceptions.ProtocolError: ('Connection aborted.', ConnectionResetError(10054, 'An existing connection was forcibly closed by the remote host', None, 10054, None))

During handling of the above exception, another exception occurred:

Traceback (most recent call last):
  File "D:\Projects\RAG\frontend\app.py", line 32, in <module>
    response = requests.post(
               ^^^^^^^^^^^^^^
  File "C:\Users\harsh\miniconda3\Lib\site-packages\requests\api.py", line 115, in post
    return request("post", url, data=data, json=json, **kwargs)
           ^^^^^^^^^^^^^^^^^^^^^^^^^^^^^^^^^^^^^^^^^^^^^^^^^^^^
  File "C:\Users\harsh\miniconda3\Lib\site-packages\requests\api.py", line 59, in request
    return session.request(method=method, url=url, **kwargs)
           ^^^^^^^^^^^^^^^^^^^^^^^^^^^^^^^^^^^^^^^^^^^^^^^^^
  File "C:\Users\harsh\miniconda3\Lib\site-packages\requests\sessions.py", line 589, in request
    resp = self.send(prep, **send_kwargs)
           ^^^^^^^^^^^^^^^^^^^^^^^^^^^^^^
  File "C:\Users\harsh\miniconda3\Lib\site-packages\requests\sessions.py", line 703, in send
    r = adapter.send(request, **kwargs)
        ^^^^^^^^^^^^^^^^^^^^^^^^^^^^^^^
  File "C:\Users\harsh\miniconda3\Lib\site-packages\requests\adapters.py", line 682, in send
    raise ConnectionError(err, request=request)
requests.exceptions.ConnectionError: ('Connection aborted.', ConnectionResetError(10054, 'An existing connection was forcibly closed by the remote host', None, 10054, None))
Request sent to FastAPI backend.
Successful response received from FastAPI backend.
Request sent to FastAPI backend.
Successful response received from FastAPI backend.
Request sent to FastAPI backend.
Successful response received from FastAPI backend.
Request sent to FastAPI backend.
Successful response received from FastAPI backend.
Request sent to FastAPI backend.
Successful response received from FastAPI backend.
Request sent to FastAPI backend.
Successful response received from FastAPI backend.
An error occurred: HTTPConnectionPool(host='localhost', port=9000): Max retries exceeded with url: /api/ragas (Caused by NewConnectionError('<urllib3.connection.HTTPConnection object at 0x00000233C247E510>: Failed to establish a new connection: [WinError 10061] No connection could be made because the target machine actively refused it'))
Traceback (most recent call last):
  File "C:\Users\harsh\miniconda3\Lib\site-packages\urllib3\connection.py", line 203, in _new_conn
    sock = connection.create_connection(
           ^^^^^^^^^^^^^^^^^^^^^^^^^^^^^
  File "C:\Users\harsh\miniconda3\Lib\site-packages\urllib3\util\connection.py", line 85, in create_connection
    raise err
  File "C:\Users\harsh\miniconda3\Lib\site-packages\urllib3\util\connection.py", line 73, in create_connection
    sock.connect(sa)
ConnectionRefusedError: [WinError 10061] No connection could be made because the target machine actively refused it

The above exception was the direct cause of the following exception:

Traceback (most recent call last):
  File "C:\Users\harsh\miniconda3\Lib\site-packages\urllib3\connectionpool.py", line 790, in urlopen
    response = self._make_request(
               ^^^^^^^^^^^^^^^^^^^
  File "C:\Users\harsh\miniconda3\Lib\site-packages\urllib3\connectionpool.py", line 496, in _make_request
    conn.request(
  File "C:\Users\harsh\miniconda3\Lib\site-packages\urllib3\connection.py", line 395, in request
    self.endheaders()
  File "C:\Users\harsh\miniconda3\Lib\http\client.py", line 1326, in endheaders
    self._send_output(message_body, encode_chunked=encode_chunked)
  File "C:\Users\harsh\miniconda3\Lib\http\client.py", line 1085, in _send_output
    self.send(msg)
  File "C:\Users\harsh\miniconda3\Lib\http\client.py", line 1029, in send
    self.connect()
  File "C:\Users\harsh\miniconda3\Lib\site-packages\urllib3\connection.py", line 243, in connect
    self.sock = self._new_conn()
                ^^^^^^^^^^^^^^^^
  File "C:\Users\harsh\miniconda3\Lib\site-packages\urllib3\connection.py", line 218, in _new_conn
    raise NewConnectionError(
urllib3.exceptions.NewConnectionError: <urllib3.connection.HTTPConnection object at 0x00000233C247E510>: Failed to establish a new connection: [WinError 10061] No connection could be made because the target machine actively refused it

The above exception was the direct cause of the following exception:

Traceback (most recent call last):
  File "C:\Users\harsh\miniconda3\Lib\site-packages\requests\adapters.py", line 667, in send
    resp = conn.urlopen(
           ^^^^^^^^^^^^^
  File "C:\Users\harsh\miniconda3\Lib\site-packages\urllib3\connectionpool.py", line 844, in urlopen
    retries = retries.increment(
              ^^^^^^^^^^^^^^^^^^
  File "C:\Users\harsh\miniconda3\Lib\site-packages\urllib3\util\retry.py", line 515, in increment
    raise MaxRetryError(_pool, url, reason) from reason  # type: ignore[arg-type]
    ^^^^^^^^^^^^^^^^^^^^^^^^^^^^^^^^^^^^^^^^^^^^^^^^^^^
urllib3.exceptions.MaxRetryError: HTTPConnectionPool(host='localhost', port=9000): Max retries exceeded with url: /api/ragas (Caused by NewConnectionError('<urllib3.connection.HTTPConnection object at 0x00000233C247E510>: Failed to establish a new connection: [WinError 10061] No connection could be made because the target machine actively refused it'))

During handling of the above exception, another exception occurred:

Traceback (most recent call last):
  File "D:\Projects\RAG\frontend\app.py", line 32, in <module>
    response = requests.post(
               ^^^^^^^^^^^^^^
  File "C:\Users\harsh\miniconda3\Lib\site-packages\requests\api.py", line 115, in post
    return request("post", url, data=data, json=json, **kwargs)
           ^^^^^^^^^^^^^^^^^^^^^^^^^^^^^^^^^^^^^^^^^^^^^^^^^^^^
  File "C:\Users\harsh\miniconda3\Lib\site-packages\requests\api.py", line 59, in request
    return session.request(method=method, url=url, **kwargs)
           ^^^^^^^^^^^^^^^^^^^^^^^^^^^^^^^^^^^^^^^^^^^^^^^^^
  File "C:\Users\harsh\miniconda3\Lib\site-packages\requests\sessions.py", line 589, in request
    resp = self.send(prep, **send_kwargs)
           ^^^^^^^^^^^^^^^^^^^^^^^^^^^^^^
  File "C:\Users\harsh\miniconda3\Lib\site-packages\requests\sessions.py", line 703, in send
    r = adapter.send(request, **kwargs)
        ^^^^^^^^^^^^^^^^^^^^^^^^^^^^^^^
  File "C:\Users\harsh\miniconda3\Lib\site-packages\requests\adapters.py", line 700, in send
    raise ConnectionError(e, request=request)
requests.exceptions.ConnectionError: HTTPConnectionPool(host='localhost', port=9000): Max retries exceeded with url: /api/ragas (Caused by NewConnectionError('<urllib3.connection.HTTPConnection object at 0x00000233C247E510>: Failed to establish a new connection: [WinError 10061] No connection could be made because the target machine actively refused it'))
Request sent to FastAPI backend.
Successful response received from FastAPI backend.
Request sent to FastAPI backend.
Successful response received from FastAPI backend.
Request sent to FastAPI backend.
Successful response received from FastAPI backend.
Request sent to FastAPI backend.
Successful response received from FastAPI backend.
Request sent to FastAPI backend.
Successful response received from FastAPI backend.
Request sent to FastAPI backend.
Successful response received from FastAPI backend.
An error occurred: HTTPConnectionPool(host='localhost', port=9000): Max retries exceeded with url: /api/ragas (Caused by NewConnectionError('<urllib3.connection.HTTPConnection object at 0x000001A9BA3B6120>: Failed to establish a new connection: [WinError 10061] No connection could be made because the target machine actively refused it'))
Traceback (most recent call last):
  File "C:\Users\harsh\miniconda3\Lib\site-packages\urllib3\connection.py", line 203, in _new_conn
    sock = connection.create_connection(
           ^^^^^^^^^^^^^^^^^^^^^^^^^^^^^
  File "C:\Users\harsh\miniconda3\Lib\site-packages\urllib3\util\connection.py", line 85, in create_connection
    raise err
  File "C:\Users\harsh\miniconda3\Lib\site-packages\urllib3\util\connection.py", line 73, in create_connection
    sock.connect(sa)
ConnectionRefusedError: [WinError 10061] No connection could be made because the target machine actively refused it

The above exception was the direct cause of the following exception:

Traceback (most recent call last):
  File "C:\Users\harsh\miniconda3\Lib\site-packages\urllib3\connectionpool.py", line 790, in urlopen
    response = self._make_request(
               ^^^^^^^^^^^^^^^^^^^
  File "C:\Users\harsh\miniconda3\Lib\site-packages\urllib3\connectionpool.py", line 496, in _make_request
    conn.request(
  File "C:\Users\harsh\miniconda3\Lib\site-packages\urllib3\connection.py", line 395, in request
    self.endheaders()
  File "C:\Users\harsh\miniconda3\Lib\http\client.py", line 1326, in endheaders
    self._send_output(message_body, encode_chunked=encode_chunked)
  File "C:\Users\harsh\miniconda3\Lib\http\client.py", line 1085, in _send_output
    self.send(msg)
  File "C:\Users\harsh\miniconda3\Lib\http\client.py", line 1029, in send
    self.connect()
  File "C:\Users\harsh\miniconda3\Lib\site-packages\urllib3\connection.py", line 243, in connect
    self.sock = self._new_conn()
                ^^^^^^^^^^^^^^^^
  File "C:\Users\harsh\miniconda3\Lib\site-packages\urllib3\connection.py", line 218, in _new_conn
    raise NewConnectionError(
urllib3.exceptions.NewConnectionError: <urllib3.connection.HTTPConnection object at 0x000001A9BA3B6120>: Failed to establish a new connection: [WinError 10061] No connection could be made because the target machine actively refused it

The above exception was the direct cause of the following exception:

Traceback (most recent call last):
  File "C:\Users\harsh\miniconda3\Lib\site-packages\requests\adapters.py", line 667, in send
    resp = conn.urlopen(
           ^^^^^^^^^^^^^
  File "C:\Users\harsh\miniconda3\Lib\site-packages\urllib3\connectionpool.py", line 844, in urlopen
    retries = retries.increment(
              ^^^^^^^^^^^^^^^^^^
  File "C:\Users\harsh\miniconda3\Lib\site-packages\urllib3\util\retry.py", line 515, in increment
    raise MaxRetryError(_pool, url, reason) from reason  # type: ignore[arg-type]
    ^^^^^^^^^^^^^^^^^^^^^^^^^^^^^^^^^^^^^^^^^^^^^^^^^^^
urllib3.exceptions.MaxRetryError: HTTPConnectionPool(host='localhost', port=9000): Max retries exceeded with url: /api/ragas (Caused by NewConnectionError('<urllib3.connection.HTTPConnection object at 0x000001A9BA3B6120>: Failed to establish a new connection: [WinError 10061] No connection could be made because the target machine actively refused it'))

During handling of the above exception, another exception occurred:

Traceback (most recent call last):
  File "D:\Projects\RAG\frontend\app.py", line 32, in <module>
    response = requests.post(
               ^^^^^^^^^^^^^^
  File "C:\Users\harsh\miniconda3\Lib\site-packages\requests\api.py", line 115, in post
    return request("post", url, data=data, json=json, **kwargs)
           ^^^^^^^^^^^^^^^^^^^^^^^^^^^^^^^^^^^^^^^^^^^^^^^^^^^^
  File "C:\Users\harsh\miniconda3\Lib\site-packages\requests\api.py", line 59, in request
    return session.request(method=method, url=url, **kwargs)
           ^^^^^^^^^^^^^^^^^^^^^^^^^^^^^^^^^^^^^^^^^^^^^^^^^
  File "C:\Users\harsh\miniconda3\Lib\site-packages\requests\sessions.py", line 589, in request
    resp = self.send(prep, **send_kwargs)
           ^^^^^^^^^^^^^^^^^^^^^^^^^^^^^^
  File "C:\Users\harsh\miniconda3\Lib\site-packages\requests\sessions.py", line 703, in send
    r = adapter.send(request, **kwargs)
        ^^^^^^^^^^^^^^^^^^^^^^^^^^^^^^^
  File "C:\Users\harsh\miniconda3\Lib\site-packages\requests\adapters.py", line 700, in send
    raise ConnectionError(e, request=request)
requests.exceptions.ConnectionError: HTTPConnectionPool(host='localhost', port=9000): Max retries exceeded with url: /api/ragas (Caused by NewConnectionError('<urllib3.connection.HTTPConnection object at 0x000001A9BA3B6120>: Failed to establish a new connection: [WinError 10061] No connection could be made because the target machine actively refused it'))
An error occurred: HTTPConnectionPool(host='localhost', port=9000): Max retries exceeded with url: /api/ragas (Caused by NewConnectionError('<urllib3.connection.HTTPConnection object at 0x000001A9BA266C30>: Failed to establish a new connection: [WinError 10061] No connection could be made because the target machine actively refused it'))
Traceback (most recent call last):
  File "C:\Users\harsh\miniconda3\Lib\site-packages\urllib3\connection.py", line 203, in _new_conn
    sock = connection.create_connection(
           ^^^^^^^^^^^^^^^^^^^^^^^^^^^^^
  File "C:\Users\harsh\miniconda3\Lib\site-packages\urllib3\util\connection.py", line 85, in create_connection
    raise err
  File "C:\Users\harsh\miniconda3\Lib\site-packages\urllib3\util\connection.py", line 73, in create_connection
    sock.connect(sa)
ConnectionRefusedError: [WinError 10061] No connection could be made because the target machine actively refused it

The above exception was the direct cause of the following exception:

Traceback (most recent call last):
  File "C:\Users\harsh\miniconda3\Lib\site-packages\urllib3\connectionpool.py", line 790, in urlopen
    response = self._make_request(
               ^^^^^^^^^^^^^^^^^^^
  File "C:\Users\harsh\miniconda3\Lib\site-packages\urllib3\connectionpool.py", line 496, in _make_request
    conn.request(
  File "C:\Users\harsh\miniconda3\Lib\site-packages\urllib3\connection.py", line 395, in request
    self.endheaders()
  File "C:\Users\harsh\miniconda3\Lib\http\client.py", line 1326, in endheaders
    self._send_output(message_body, encode_chunked=encode_chunked)
  File "C:\Users\harsh\miniconda3\Lib\http\client.py", line 1085, in _send_output
    self.send(msg)
  File "C:\Users\harsh\miniconda3\Lib\http\client.py", line 1029, in send
    self.connect()
  File "C:\Users\harsh\miniconda3\Lib\site-packages\urllib3\connection.py", line 243, in connect
    self.sock = self._new_conn()
                ^^^^^^^^^^^^^^^^
  File "C:\Users\harsh\miniconda3\Lib\site-packages\urllib3\connection.py", line 218, in _new_conn
    raise NewConnectionError(
urllib3.exceptions.NewConnectionError: <urllib3.connection.HTTPConnection object at 0x000001A9BA266C30>: Failed to establish a new connection: [WinError 10061] No connection could be made because the target machine actively refused it

The above exception was the direct cause of the following exception:

Traceback (most recent call last):
  File "C:\Users\harsh\miniconda3\Lib\site-packages\requests\adapters.py", line 667, in send
    resp = conn.urlopen(
           ^^^^^^^^^^^^^
  File "C:\Users\harsh\miniconda3\Lib\site-packages\urllib3\connectionpool.py", line 844, in urlopen
    retries = retries.increment(
              ^^^^^^^^^^^^^^^^^^
  File "C:\Users\harsh\miniconda3\Lib\site-packages\urllib3\util\retry.py", line 515, in increment
    raise MaxRetryError(_pool, url, reason) from reason  # type: ignore[arg-type]
    ^^^^^^^^^^^^^^^^^^^^^^^^^^^^^^^^^^^^^^^^^^^^^^^^^^^
urllib3.exceptions.MaxRetryError: HTTPConnectionPool(host='localhost', port=9000): Max retries exceeded with url: /api/ragas (Caused by NewConnectionError('<urllib3.connection.HTTPConnection object at 0x000001A9BA266C30>: Failed to establish a new connection: [WinError 10061] No connection could be made because the target machine actively refused it'))

During handling of the above exception, another exception occurred:

Traceback (most recent call last):
  File "D:\Projects\RAG\frontend\app.py", line 32, in <module>
    response = requests.post(
               ^^^^^^^^^^^^^^
  File "C:\Users\harsh\miniconda3\Lib\site-packages\requests\api.py", line 115, in post
    return request("post", url, data=data, json=json, **kwargs)
           ^^^^^^^^^^^^^^^^^^^^^^^^^^^^^^^^^^^^^^^^^^^^^^^^^^^^
  File "C:\Users\harsh\miniconda3\Lib\site-packages\requests\api.py", line 59, in request
    return session.request(method=method, url=url, **kwargs)
           ^^^^^^^^^^^^^^^^^^^^^^^^^^^^^^^^^^^^^^^^^^^^^^^^^
  File "C:\Users\harsh\miniconda3\Lib\site-packages\requests\sessions.py", line 589, in request
    resp = self.send(prep, **send_kwargs)
           ^^^^^^^^^^^^^^^^^^^^^^^^^^^^^^
  File "C:\Users\harsh\miniconda3\Lib\site-packages\requests\sessions.py", line 703, in send
    r = adapter.send(request, **kwargs)
        ^^^^^^^^^^^^^^^^^^^^^^^^^^^^^^^
  File "C:\Users\harsh\miniconda3\Lib\site-packages\requests\adapters.py", line 700, in send
    raise ConnectionError(e, request=request)
requests.exceptions.ConnectionError: HTTPConnectionPool(host='localhost', port=9000): Max retries exceeded with url: /api/ragas (Caused by NewConnectionError('<urllib3.connection.HTTPConnection object at 0x000001A9BA266C30>: Failed to establish a new connection: [WinError 10061] No connection could be made because the target machine actively refused it'))
Request sent to FastAPI backend.
Successful response received from FastAPI backend.
Request sent to FastAPI backend.
Successful response received from FastAPI backend.
Request sent to FastAPI backend.
Successful response received from FastAPI backend.
Request sent to FastAPI backend.
Successful response received from FastAPI backend.
Request sent to FastAPI backend.
Successful response received from FastAPI backend.
Request sent to FastAPI backend.
Successful response received from FastAPI backend.
Request sent to FastAPI backend.
Successful response received from FastAPI backend.
Request sent to FastAPI backend.
Successful response received from FastAPI backend.
Request sent to FastAPI backend.
Successful response received from FastAPI backend.
Request sent to FastAPI backend.
Successful response received from FastAPI backend.
Request sent to FastAPI backend.
Successful response received from FastAPI backend.
Request sent to FastAPI backend.
Successful response received from FastAPI backend.
Request sent to FastAPI backend.
Successful response received from FastAPI backend.
Request sent to FastAPI backend.
Successful response received from FastAPI backend.
An error occurred: ('Connection aborted.', ConnectionResetError(10054, 'An existing connection was forcibly closed by the remote host', None, 10054, None))
Traceback (most recent call last):
  File "C:\Users\harsh\miniconda3\Lib\site-packages\urllib3\connectionpool.py", line 790, in urlopen
    response = self._make_request(
               ^^^^^^^^^^^^^^^^^^^
  File "C:\Users\harsh\miniconda3\Lib\site-packages\urllib3\connectionpool.py", line 536, in _make_request
    response = conn.getresponse()
               ^^^^^^^^^^^^^^^^^^
  File "C:\Users\harsh\miniconda3\Lib\site-packages\urllib3\connection.py", line 461, in getresponse
    httplib_response = super().getresponse()
                       ^^^^^^^^^^^^^^^^^^^^^
  File "C:\Users\harsh\miniconda3\Lib\http\client.py", line 1423, in getresponse
    response.begin()
  File "C:\Users\harsh\miniconda3\Lib\http\client.py", line 331, in begin
    version, status, reason = self._read_status()
                              ^^^^^^^^^^^^^^^^^^^
  File "C:\Users\harsh\miniconda3\Lib\http\client.py", line 292, in _read_status
    line = str(self.fp.readline(_MAXLINE + 1), "iso-8859-1")
               ^^^^^^^^^^^^^^^^^^^^^^^^^^^^^^
  File "C:\Users\harsh\miniconda3\Lib\socket.py", line 707, in readinto
    return self._sock.recv_into(b)
           ^^^^^^^^^^^^^^^^^^^^^^^
ConnectionResetError: [WinError 10054] An existing connection was forcibly closed by the remote host

During handling of the above exception, another exception occurred:

Traceback (most recent call last):
  File "C:\Users\harsh\miniconda3\Lib\site-packages\requests\adapters.py", line 667, in send
    resp = conn.urlopen(
           ^^^^^^^^^^^^^
  File "C:\Users\harsh\miniconda3\Lib\site-packages\urllib3\connectionpool.py", line 844, in urlopen
    retries = retries.increment(
              ^^^^^^^^^^^^^^^^^^
  File "C:\Users\harsh\miniconda3\Lib\site-packages\urllib3\util\retry.py", line 470, in increment
    raise reraise(type(error), error, _stacktrace)
          ^^^^^^^^^^^^^^^^^^^^^^^^^^^^^^^^^^^^^^^^
  File "C:\Users\harsh\miniconda3\Lib\site-packages\urllib3\util\util.py", line 38, in reraise
    raise value.with_traceback(tb)
  File "C:\Users\harsh\miniconda3\Lib\site-packages\urllib3\connectionpool.py", line 790, in urlopen
    response = self._make_request(
               ^^^^^^^^^^^^^^^^^^^
  File "C:\Users\harsh\miniconda3\Lib\site-packages\urllib3\connectionpool.py", line 536, in _make_request
    response = conn.getresponse()
               ^^^^^^^^^^^^^^^^^^
  File "C:\Users\harsh\miniconda3\Lib\site-packages\urllib3\connection.py", line 461, in getresponse
    httplib_response = super().getresponse()
                       ^^^^^^^^^^^^^^^^^^^^^
  File "C:\Users\harsh\miniconda3\Lib\http\client.py", line 1423, in getresponse
    response.begin()
  File "C:\Users\harsh\miniconda3\Lib\http\client.py", line 331, in begin
    version, status, reason = self._read_status()
                              ^^^^^^^^^^^^^^^^^^^
  File "C:\Users\harsh\miniconda3\Lib\http\client.py", line 292, in _read_status
    line = str(self.fp.readline(_MAXLINE + 1), "iso-8859-1")
               ^^^^^^^^^^^^^^^^^^^^^^^^^^^^^^
  File "C:\Users\harsh\miniconda3\Lib\socket.py", line 707, in readinto
    return self._sock.recv_into(b)
           ^^^^^^^^^^^^^^^^^^^^^^^
urllib3.exceptions.ProtocolError: ('Connection aborted.', ConnectionResetError(10054, 'An existing connection was forcibly closed by the remote host', None, 10054, None))

During handling of the above exception, another exception occurred:

Traceback (most recent call last):
  File "D:\Projects\RAG\frontend\app.py", line 32, in <module>
    response = requests.post(
               ^^^^^^^^^^^^^^
  File "C:\Users\harsh\miniconda3\Lib\site-packages\requests\api.py", line 115, in post
    return request("post", url, data=data, json=json, **kwargs)
           ^^^^^^^^^^^^^^^^^^^^^^^^^^^^^^^^^^^^^^^^^^^^^^^^^^^^
  File "C:\Users\harsh\miniconda3\Lib\site-packages\requests\api.py", line 59, in request
    return session.request(method=method, url=url, **kwargs)
           ^^^^^^^^^^^^^^^^^^^^^^^^^^^^^^^^^^^^^^^^^^^^^^^^^
  File "C:\Users\harsh\miniconda3\Lib\site-packages\requests\sessions.py", line 589, in request
    resp = self.send(prep, **send_kwargs)
           ^^^^^^^^^^^^^^^^^^^^^^^^^^^^^^
  File "C:\Users\harsh\miniconda3\Lib\site-packages\requests\sessions.py", line 703, in send
    r = adapter.send(request, **kwargs)
        ^^^^^^^^^^^^^^^^^^^^^^^^^^^^^^^
  File "C:\Users\harsh\miniconda3\Lib\site-packages\requests\adapters.py", line 682, in send
    raise ConnectionError(err, request=request)
requests.exceptions.ConnectionError: ('Connection aborted.', ConnectionResetError(10054, 'An existing connection was forcibly closed by the remote host', None, 10054, None))
Request sent to FastAPI backend.
Successful response received from FastAPI backend.
Request sent to FastAPI backend.
Successful response received from FastAPI backend.
Request sent to FastAPI backend.
Successful response received from FastAPI backend.
Request sent to FastAPI backend.
Successful response received from FastAPI backend.
Request sent to FastAPI backend.
Successful response received from FastAPI backend.
Request sent to FastAPI backend.
Successful response received from FastAPI backend.
Request sent to FastAPI backend.
Successful response received from FastAPI backend.
Request sent to FastAPI backend.
Successful response received from FastAPI backend.
Request sent to FastAPI backend.
Successful response received from FastAPI backend.
Request sent to FastAPI backend.
Successful response received from FastAPI backend.
Request sent to FastAPI backend.
Successful response received from FastAPI backend.
Request sent to FastAPI backend.
Successful response received from FastAPI backend.
Request sent to FastAPI backend.
Successful response received from FastAPI backend.
Request sent to FastAPI backend.
Successful response received from FastAPI backend.
Request sent to FastAPI backend.
Successful response received from FastAPI backend.
Request sent to FastAPI backend.
Successful response received from FastAPI backend.
An error occurred: HTTPConnectionPool(host='localhost', port=9000): Max retries exceeded with url: /api/ragas (Caused by NewConnectionError('<urllib3.connection.HTTPConnection object at 0x0000025FCA65B740>: Failed to establish a new connection: [WinError 10061] No connection could be made because the target machine actively refused it'))
Traceback (most recent call last):
  File "C:\Users\harsh\miniconda3\Lib\site-packages\urllib3\connection.py", line 203, in _new_conn
    sock = connection.create_connection(
           ^^^^^^^^^^^^^^^^^^^^^^^^^^^^^
  File "C:\Users\harsh\miniconda3\Lib\site-packages\urllib3\util\connection.py", line 85, in create_connection
    raise err
  File "C:\Users\harsh\miniconda3\Lib\site-packages\urllib3\util\connection.py", line 73, in create_connection
    sock.connect(sa)
ConnectionRefusedError: [WinError 10061] No connection could be made because the target machine actively refused it

The above exception was the direct cause of the following exception:

Traceback (most recent call last):
  File "C:\Users\harsh\miniconda3\Lib\site-packages\urllib3\connectionpool.py", line 790, in urlopen
    response = self._make_request(
               ^^^^^^^^^^^^^^^^^^^
  File "C:\Users\harsh\miniconda3\Lib\site-packages\urllib3\connectionpool.py", line 496, in _make_request
    conn.request(
  File "C:\Users\harsh\miniconda3\Lib\site-packages\urllib3\connection.py", line 395, in request
    self.endheaders()
  File "C:\Users\harsh\miniconda3\Lib\http\client.py", line 1326, in endheaders
    self._send_output(message_body, encode_chunked=encode_chunked)
  File "C:\Users\harsh\miniconda3\Lib\http\client.py", line 1085, in _send_output
    self.send(msg)
  File "C:\Users\harsh\miniconda3\Lib\http\client.py", line 1029, in send
    self.connect()
  File "C:\Users\harsh\miniconda3\Lib\site-packages\urllib3\connection.py", line 243, in connect
    self.sock = self._new_conn()
                ^^^^^^^^^^^^^^^^
  File "C:\Users\harsh\miniconda3\Lib\site-packages\urllib3\connection.py", line 218, in _new_conn
    raise NewConnectionError(
urllib3.exceptions.NewConnectionError: <urllib3.connection.HTTPConnection object at 0x0000025FCA65B740>: Failed to establish a new connection: [WinError 10061] No connection could be made because the target machine actively refused it

The above exception was the direct cause of the following exception:

Traceback (most recent call last):
  File "C:\Users\harsh\miniconda3\Lib\site-packages\requests\adapters.py", line 667, in send
    resp = conn.urlopen(
           ^^^^^^^^^^^^^
  File "C:\Users\harsh\miniconda3\Lib\site-packages\urllib3\connectionpool.py", line 844, in urlopen
    retries = retries.increment(
              ^^^^^^^^^^^^^^^^^^
  File "C:\Users\harsh\miniconda3\Lib\site-packages\urllib3\util\retry.py", line 515, in increment
    raise MaxRetryError(_pool, url, reason) from reason  # type: ignore[arg-type]
    ^^^^^^^^^^^^^^^^^^^^^^^^^^^^^^^^^^^^^^^^^^^^^^^^^^^
urllib3.exceptions.MaxRetryError: HTTPConnectionPool(host='localhost', port=9000): Max retries exceeded with url: /api/ragas (Caused by NewConnectionError('<urllib3.connection.HTTPConnection object at 0x0000025FCA65B740>: Failed to establish a new connection: [WinError 10061] No connection could be made because the target machine actively refused it'))

During handling of the above exception, another exception occurred:

Traceback (most recent call last):
  File "D:\Projects\RAG\frontend\app.py", line 35, in <module>
    response = requests.post(
               ^^^^^^^^^^^^^^
  File "C:\Users\harsh\miniconda3\Lib\site-packages\requests\api.py", line 115, in post
    return request("post", url, data=data, json=json, **kwargs)
           ^^^^^^^^^^^^^^^^^^^^^^^^^^^^^^^^^^^^^^^^^^^^^^^^^^^^
  File "C:\Users\harsh\miniconda3\Lib\site-packages\requests\api.py", line 59, in request
    return session.request(method=method, url=url, **kwargs)
           ^^^^^^^^^^^^^^^^^^^^^^^^^^^^^^^^^^^^^^^^^^^^^^^^^
  File "C:\Users\harsh\miniconda3\Lib\site-packages\requests\sessions.py", line 589, in request
    resp = self.send(prep, **send_kwargs)
           ^^^^^^^^^^^^^^^^^^^^^^^^^^^^^^
  File "C:\Users\harsh\miniconda3\Lib\site-packages\requests\sessions.py", line 703, in send
    r = adapter.send(request, **kwargs)
        ^^^^^^^^^^^^^^^^^^^^^^^^^^^^^^^
  File "C:\Users\harsh\miniconda3\Lib\site-packages\requests\adapters.py", line 700, in send
    raise ConnectionError(e, request=request)
requests.exceptions.ConnectionError: HTTPConnectionPool(host='localhost', port=9000): Max retries exceeded with url: /api/ragas (Caused by NewConnectionError('<urllib3.connection.HTTPConnection object at 0x0000025FCA65B740>: Failed to establish a new connection: [WinError 10061] No connection could be made because the target machine actively refused it'))
An error occurred: HTTPConnectionPool(host='localhost', port=9000): Max retries exceeded with url: /api/ragas (Caused by NewConnectionError('<urllib3.connection.HTTPConnection object at 0x0000025FCA65B740>: Failed to establish a new connection: [WinError 10061] No connection could be made because the target machine actively refused it'))
Traceback (most recent call last):
  File "C:\Users\harsh\miniconda3\Lib\site-packages\urllib3\connection.py", line 203, in _new_conn
    sock = connection.create_connection(
           ^^^^^^^^^^^^^^^^^^^^^^^^^^^^^
  File "C:\Users\harsh\miniconda3\Lib\site-packages\urllib3\util\connection.py", line 85, in create_connection
    raise err
  File "C:\Users\harsh\miniconda3\Lib\site-packages\urllib3\util\connection.py", line 73, in create_connection
    sock.connect(sa)
ConnectionRefusedError: [WinError 10061] No connection could be made because the target machine actively refused it

The above exception was the direct cause of the following exception:

Traceback (most recent call last):
  File "C:\Users\harsh\miniconda3\Lib\site-packages\urllib3\connectionpool.py", line 790, in urlopen
    response = self._make_request(
               ^^^^^^^^^^^^^^^^^^^
  File "C:\Users\harsh\miniconda3\Lib\site-packages\urllib3\connectionpool.py", line 496, in _make_request
    conn.request(
  File "C:\Users\harsh\miniconda3\Lib\site-packages\urllib3\connection.py", line 395, in request
    self.endheaders()
  File "C:\Users\harsh\miniconda3\Lib\http\client.py", line 1326, in endheaders
    self._send_output(message_body, encode_chunked=encode_chunked)
  File "C:\Users\harsh\miniconda3\Lib\http\client.py", line 1085, in _send_output
    self.send(msg)
  File "C:\Users\harsh\miniconda3\Lib\http\client.py", line 1029, in send
    self.connect()
  File "C:\Users\harsh\miniconda3\Lib\site-packages\urllib3\connection.py", line 243, in connect
    self.sock = self._new_conn()
                ^^^^^^^^^^^^^^^^
  File "C:\Users\harsh\miniconda3\Lib\site-packages\urllib3\connection.py", line 218, in _new_conn
    raise NewConnectionError(
urllib3.exceptions.NewConnectionError: <urllib3.connection.HTTPConnection object at 0x0000025FCA65B740>: Failed to establish a new connection: [WinError 10061] No connection could be made because the target machine actively refused it

The above exception was the direct cause of the following exception:

Traceback (most recent call last):
  File "C:\Users\harsh\miniconda3\Lib\site-packages\requests\adapters.py", line 667, in send
    resp = conn.urlopen(
           ^^^^^^^^^^^^^
  File "C:\Users\harsh\miniconda3\Lib\site-packages\urllib3\connectionpool.py", line 844, in urlopen
    retries = retries.increment(
              ^^^^^^^^^^^^^^^^^^
  File "C:\Users\harsh\miniconda3\Lib\site-packages\urllib3\util\retry.py", line 515, in increment
    raise MaxRetryError(_pool, url, reason) from reason  # type: ignore[arg-type]
    ^^^^^^^^^^^^^^^^^^^^^^^^^^^^^^^^^^^^^^^^^^^^^^^^^^^
urllib3.exceptions.MaxRetryError: HTTPConnectionPool(host='localhost', port=9000): Max retries exceeded with url: /api/ragas (Caused by NewConnectionError('<urllib3.connection.HTTPConnection object at 0x0000025FCA65B740>: Failed to establish a new connection: [WinError 10061] No connection could be made because the target machine actively refused it'))

During handling of the above exception, another exception occurred:

Traceback (most recent call last):
  File "D:\Projects\RAG\frontend\app.py", line 35, in <module>
    response = requests.post(
               ^^^^^^^^^^^^^^
  File "C:\Users\harsh\miniconda3\Lib\site-packages\requests\api.py", line 115, in post
    return request("post", url, data=data, json=json, **kwargs)
           ^^^^^^^^^^^^^^^^^^^^^^^^^^^^^^^^^^^^^^^^^^^^^^^^^^^^
  File "C:\Users\harsh\miniconda3\Lib\site-packages\requests\api.py", line 59, in request
    return session.request(method=method, url=url, **kwargs)
           ^^^^^^^^^^^^^^^^^^^^^^^^^^^^^^^^^^^^^^^^^^^^^^^^^
  File "C:\Users\harsh\miniconda3\Lib\site-packages\requests\sessions.py", line 589, in request
    resp = self.send(prep, **send_kwargs)
           ^^^^^^^^^^^^^^^^^^^^^^^^^^^^^^
  File "C:\Users\harsh\miniconda3\Lib\site-packages\requests\sessions.py", line 703, in send
    r = adapter.send(request, **kwargs)
        ^^^^^^^^^^^^^^^^^^^^^^^^^^^^^^^
  File "C:\Users\harsh\miniconda3\Lib\site-packages\requests\adapters.py", line 700, in send
    raise ConnectionError(e, request=request)
requests.exceptions.ConnectionError: HTTPConnectionPool(host='localhost', port=9000): Max retries exceeded with url: /api/ragas (Caused by NewConnectionError('<urllib3.connection.HTTPConnection object at 0x0000025FCA65B740>: Failed to establish a new connection: [WinError 10061] No connection could be made because the target machine actively refused it'))
Request sent to FastAPI backend.
Request sent to FastAPI backend.
Error: 422 - {"detail":[{"type":"missing","loc":["body","files"],"msg":"Field required","input":null}]}
Error: 422 - {"detail":[{"type":"missing","loc":["body","files"],"msg":"Field required","input":null}]}
Request sent to FastAPI backend.
Request sent to FastAPI backend.
Error: 422 - {"detail":[{"type":"missing","loc":["body","files"],"msg":"Field required","input":null}]}
Error: 422 - {"detail":[{"type":"missing","loc":["body","files"],"msg":"Field required","input":null}]}
Request sent to FastAPI backend.
Request sent to FastAPI backend.
Error: 422 - {"detail":[{"type":"missing","loc":["body","files"],"msg":"Field required","input":null}]}
Error: 422 - {"detail":[{"type":"missing","loc":["body","files"],"msg":"Field required","input":null}]}
Request sent to FastAPI backend.
Request sent to FastAPI backend.
Error: 422 - {"detail":[{"type":"missing","loc":["body","files"],"msg":"Field required","input":null}]}
Error: 422 - {"detail":[{"type":"missing","loc":["body","files"],"msg":"Field required","input":null}]}
No PDF was uploaded by the user.
No PDF was uploaded by the user.
No PDF was uploaded by the user.
Request sent to FastAPI backend.
Request sent to FastAPI backend.
Request sent to FastAPI backend.
Error: 422 - {"detail":[{"type":"missing","loc":["body","files"],"msg":"Field required","input":null}]}
Error: 422 - {"detail":[{"type":"missing","loc":["body","files"],"msg":"Field required","input":null}]}
Error: 422 - {"detail":[{"type":"missing","loc":["body","files"],"msg":"Field required","input":null}]}
Request sent to FastAPI backend.
Request sent to FastAPI backend.
Request sent to FastAPI backend.
Request sent to FastAPI backend.
Error: 422 - {"detail":[{"type":"missing","loc":["body","files"],"msg":"Field required","input":null}]}
Error: 422 - {"detail":[{"type":"missing","loc":["body","files"],"msg":"Field required","input":null}]}
Error: 422 - {"detail":[{"type":"missing","loc":["body","files"],"msg":"Field required","input":null}]}
Error: 422 - {"detail":[{"type":"missing","loc":["body","files"],"msg":"Field required","input":null}]}
Request sent to FastAPI backend.
Request sent to FastAPI backend.
Request sent to FastAPI backend.
Request sent to FastAPI backend.
Error: 422 - {"detail":[{"type":"missing","loc":["body","files"],"msg":"Field required","input":null}]}
Error: 422 - {"detail":[{"type":"missing","loc":["body","files"],"msg":"Field required","input":null}]}
Error: 422 - {"detail":[{"type":"missing","loc":["body","files"],"msg":"Field required","input":null}]}
Error: 422 - {"detail":[{"type":"missing","loc":["body","files"],"msg":"Field required","input":null}]}
An error occurred: HTTPConnectionPool(host='localhost', port=9000): Max retries exceeded with url: /api/ragas (Caused by NewConnectionError('<urllib3.connection.HTTPConnection object at 0x00000242300B2FF0>: Failed to establish a new connection: [WinError 10061] No connection could be made because the target machine actively refused it'))
Traceback (most recent call last):
  File "C:\Users\harsh\miniconda3\Lib\site-packages\urllib3\connection.py", line 203, in _new_conn
    sock = connection.create_connection(
           ^^^^^^^^^^^^^^^^^^^^^^^^^^^^^
  File "C:\Users\harsh\miniconda3\Lib\site-packages\urllib3\util\connection.py", line 85, in create_connection
    raise err
  File "C:\Users\harsh\miniconda3\Lib\site-packages\urllib3\util\connection.py", line 73, in create_connection
    sock.connect(sa)
ConnectionRefusedError: [WinError 10061] No connection could be made because the target machine actively refused it

The above exception was the direct cause of the following exception:

Traceback (most recent call last):
  File "C:\Users\harsh\miniconda3\Lib\site-packages\urllib3\connectionpool.py", line 790, in urlopen
    response = self._make_request(
               ^^^^^^^^^^^^^^^^^^^
  File "C:\Users\harsh\miniconda3\Lib\site-packages\urllib3\connectionpool.py", line 496, in _make_request
    conn.request(
  File "C:\Users\harsh\miniconda3\Lib\site-packages\urllib3\connection.py", line 395, in request
    self.endheaders()
  File "C:\Users\harsh\miniconda3\Lib\http\client.py", line 1326, in endheaders
    self._send_output(message_body, encode_chunked=encode_chunked)
  File "C:\Users\harsh\miniconda3\Lib\http\client.py", line 1085, in _send_output
    self.send(msg)
  File "C:\Users\harsh\miniconda3\Lib\http\client.py", line 1029, in send
    self.connect()
  File "C:\Users\harsh\miniconda3\Lib\site-packages\urllib3\connection.py", line 243, in connect
    self.sock = self._new_conn()
                ^^^^^^^^^^^^^^^^
  File "C:\Users\harsh\miniconda3\Lib\site-packages\urllib3\connection.py", line 218, in _new_conn
    raise NewConnectionError(
urllib3.exceptions.NewConnectionError: <urllib3.connection.HTTPConnection object at 0x00000242300B2FF0>: Failed to establish a new connection: [WinError 10061] No connection could be made because the target machine actively refused it

The above exception was the direct cause of the following exception:

Traceback (most recent call last):
  File "C:\Users\harsh\miniconda3\Lib\site-packages\requests\adapters.py", line 667, in send
    resp = conn.urlopen(
           ^^^^^^^^^^^^^
  File "C:\Users\harsh\miniconda3\Lib\site-packages\urllib3\connectionpool.py", line 844, in urlopen
    retries = retries.increment(
              ^^^^^^^^^^^^^^^^^^
  File "C:\Users\harsh\miniconda3\Lib\site-packages\urllib3\util\retry.py", line 515, in increment
    raise MaxRetryError(_pool, url, reason) from reason  # type: ignore[arg-type]
    ^^^^^^^^^^^^^^^^^^^^^^^^^^^^^^^^^^^^^^^^^^^^^^^^^^^
urllib3.exceptions.MaxRetryError: HTTPConnectionPool(host='localhost', port=9000): Max retries exceeded with url: /api/ragas (Caused by NewConnectionError('<urllib3.connection.HTTPConnection object at 0x00000242300B2FF0>: Failed to establish a new connection: [WinError 10061] No connection could be made because the target machine actively refused it'))

During handling of the above exception, another exception occurred:

Traceback (most recent call last):
  File "D:\Projects\RAG\frontend\app.py", line 35, in <module>
    response = requests.post(
               ^^^^^^^^^^^^^^
  File "C:\Users\harsh\miniconda3\Lib\site-packages\requests\api.py", line 115, in post
    return request("post", url, data=data, json=json, **kwargs)
           ^^^^^^^^^^^^^^^^^^^^^^^^^^^^^^^^^^^^^^^^^^^^^^^^^^^^
  File "C:\Users\harsh\miniconda3\Lib\site-packages\requests\api.py", line 59, in request
    return session.request(method=method, url=url, **kwargs)
           ^^^^^^^^^^^^^^^^^^^^^^^^^^^^^^^^^^^^^^^^^^^^^^^^^
  File "C:\Users\harsh\miniconda3\Lib\site-packages\requests\sessions.py", line 589, in request
    resp = self.send(prep, **send_kwargs)
           ^^^^^^^^^^^^^^^^^^^^^^^^^^^^^^
  File "C:\Users\harsh\miniconda3\Lib\site-packages\requests\sessions.py", line 703, in send
    r = adapter.send(request, **kwargs)
        ^^^^^^^^^^^^^^^^^^^^^^^^^^^^^^^
  File "C:\Users\harsh\miniconda3\Lib\site-packages\requests\adapters.py", line 700, in send
    raise ConnectionError(e, request=request)
requests.exceptions.ConnectionError: HTTPConnectionPool(host='localhost', port=9000): Max retries exceeded with url: /api/ragas (Caused by NewConnectionError('<urllib3.connection.HTTPConnection object at 0x00000242300B2FF0>: Failed to establish a new connection: [WinError 10061] No connection could be made because the target machine actively refused it'))
Request sent to FastAPI backend.
Error: 422 - {"detail":[{"type":"missing","loc":["body","files"],"msg":"Field required","input":null}]}
